Workbook

Sheet 0101
D2: PLANILLA DE RECAUDACION DIARIA DE APUESTA Y PREMIOS | M2: 2025
D4: FECHA : | E4: 45931 | G4: RECAUDACION DEL DIA: | I4: 45931
C6: 26 | D6: SALDO DEL DIA ANTERIOR | G6: PREMIOS | H6: 3234613.4
G7: EFECTIVO | H7: 6675360
G8: TOTAL | H8: =H6+H7 -> 9909973.4 | Q8: TICKET ANULADOS | AA8: TICKET PREMIADOS | AL8: TICKET VENDIDOS
C10: MATUTINA | D10: VESPERT. | E10: SIESTA | F10: TARDE | G10: NOCT. | H10: TOTAL | J10: PREMIOS | K10: EFECTIVO | L10: MONEDAS | M10: TOTAL | N10: DIFER. | Q10: M | R10: V | S10: S | T10: T | U10: N | V10: TOTAL | X10: PRES. | Y10: DIFER. | AA10: ANT | AB10: M | AC10: V | AD10: S | AE10: T | AF10: N | AG10: TOTAL | AI10: PRES | AJ10: DIFER. | AL10: M | AM10: V | AN10: S | AO10: T | AP10: N | AQ10: TOTAL | AS10: PRES. | AT10: DIFER.
H11: =SUM(H12:H15) -> 723800
B12: 001 | C12: 163900 | D12: 59400 | E12: 5500 | F12: 46600 | G12: 56800 | H12: =SUM(C12:G12) -> 332200 | I12: 001 | J12: 52500 | K12: 279700 | M12: =SUM(J12:L12) -> 332200 | N12: =H12-M12 -> 0 | Q12: 1 | T12: 3 | V12: =U12+T12+S12+R12+Q12 -> 4 | X12: 0 | Y12: =V12-X12 -> 4 | Z12: V | AA12: 4 | AB12: 1 | AG12: =AF12+AE12+AD12+AC12+AB12+AA12 -> 5 | AI12: 0 | AJ12: =AG12-AI12 -> 5 | AL12: 105 | AM12: 39 | AN12: 4 | AO12: 26 | AP12: 32 | AQ12: =AP12+AO12+AN12+AM12+AL12 -> 206 | AS12: 0 | AT12: =AQ12-AS12 -> 206
B13: 002 | C13: 123600 | D13: 99500 | E13: 5700 | F13: 2600 | G13: 2500 | H13: =SUM(C13:G13) -> 233900 | I13: 002 | J13: 49000 | K13: 184900 | M13: =SUM(J13:L13) -> 233900 | N13: =H13-M13 -> 0 | Q13: 2 | R13: 2 | U13: 1 | V13: =U13+T13+S13+R13+Q13 -> 5 | X13: 0 | Y13: =V13-X13 -> 5 | Z13: L | AA13: 2 | AG13: =AF13+AE13+AD13+AC13+AB13+AA13 -> 2 | AJ13: =AG13-AI13 -> 2 | AL13: 81 | AM13: 77 | AN13: 8 | AO13: 2 | AP13: 2 | AQ13: =AP13+AO13+AN13+AM13+AL13 -> 170 | AS13: 0 | AT13: =AQ13-AS13 -> 170
B14: 003 | C14: 0 | D14: 0 | E14: 39000 | F14: 33750 | G14: 84950 | H14: =SUM(C14:G14) -> 157700 | I14: 003 | K14: 157700 | M14: =SUM(J14:L14) -> 157700 | N14: =H14-M14 -> 0 | V14: =U14+T14+S14+R14+Q14 -> 0 | X14: 0 | Y14: =V14-X14 -> 0 | Z14: M | AG14: =AF14+AE14+AD14+AC14+AB14+AA14 -> 0 | AJ14: =AG14-AI14 -> 0 | AN14: 26 | AO14: 23 | AP14: 49 | AQ14: =AP14+AO14+AN14+AM14+AL14 -> 98 | AS14: 0 | AT14: =AQ14-AS14 -> 98
B15: 004 | H15: =SUM(C15:G15) -> 0 | I15: 004 | J15: 119000 | L15: -119000 | M15: =SUM(J15:L15) -> 0 | N15: =H15-M15 -> 0 | V15: =U15+T15+S15+R15+Q15 -> 0 | X15: 0 | Y15: =V15-X15 -> 0 | AG15: =AF15+AE15+AD15+AC15+AB15+AA15 -> 0 | AJ15: =AG15-AI15 -> 0 | AQ15: =AP15+AO15+AN15+AM15+AL15 -> 0 | AS15: 0 | AT15: =AQ15-AS15 -> 0
B16: 26/001 | C16: 175400 | D16: 129600 | E16: 18200 | F16: 28650 | G16: 86150 | H16: =SUM(C16:G16) -> 438000 | I16: 01 | J16: 219689.47 | K16: 218350 | L16: -39.47 | M16: =SUM(J16:L16) -> 438000 | N16: =H16-M16 -> 0 | Q16: 2 | R16: 1 | T16: 1 | V16: =U16+T16+S16+R16+Q16 -> 4 | X16: 0 | Y16: =V16-X16 -> 4 | Z16: 01 | AA16: 6 | AB16: 1 | AE16: 1 | AG16: =AF16+AE16+AD16+AC16+AB16+AA16 -> 8 | AJ16: =AG16-AI16 -> 8 | AK16: 01 | AL16: 108 | AM16: 103 | AN16: 27 | AO16: 36 | AP16: 68 | AQ16: =AP16+AO16+AN16+AM16+AL16 -> 342 | AS16: 0 | AT16: =AQ16-AS16 -> 342
B17: 26/002 | C17: 361950 | D17: 213750 | E17: 145350 | F17: 148350 | G17: 203350 | H17: =SUM(C17:G17) -> 1072750 | I17: 02 | J17: 442477.78 | K17: 630300 | L17: -27.78 | M17: =SUM(J17:L17) -> 1072750 | N17: =H17-M17 -> 0 | Q17: 3 | R17: 2 | T17: 4 | U17: 1 | V17: =U17+T17+S17+R17+Q17 -> 10 | X17: 0 | Y17: =V17-X17 -> 10 | Z17: 02 | AA17: 16 | AB17: 2 | AC17: 1 | AG17: =AF17+AE17+AD17+AC17+AB17+AA17 -> 19 | AJ17: =AG17-AI17 -> 19 | AK17: 02 | AL17: 228 | AM17: 155 | AN17: 109 | AO17: 125 | AP17: 157 | AQ17: =AP17+AO17+AN17+AM17+AL17 -> 774 | AS17: 0 | AT17: =AQ17-AS17 -> 774
B18: 26/003 | C18: 150500 | D18: 139400 | E18: 85800 | F18: 115600 | G18: 107000 | H18: =SUM(C18:G18) -> 598300 | I18: 03 | J18: 107800 | K18: 490500 | M18: =SUM(J18:L18) -> 598300 | N18: =H18-M18 -> 0 | V18: =U18+T18+S18+R18+Q18 -> 0 | X18: 0 | Y18: =V18-X18 -> 0 | Z18: 03 | AA18: 3 | AB18: 2 | AC18: 1 | AD18: 1 | AE18: 1 | AG18: =AF18+AE18+AD18+AC18+AB18+AA18 -> 8 | AJ18: =AG18-AI18 -> 8 | AK18: 03 | AL18: 105 | AM18: 88 | AN18: 46 | AO18: 56 | AP18: 65 | AQ18: =AP18+AO18+AN18+AM18+AL18 -> 360 | AS18: 0 | AT18: =AQ18-AS18 -> 360
B19: 26/004 | C19: 201950 | D19: 229950 | E19: 60800 | F19: 93900 | G19: 242500 | H19: =SUM(C19:G19) -> 829100 | I19: 04 | J19: 113400 | K19: 711700 | M19: =SUM(J19:L19) -> 825100 | N19: =H19-M19 -> 4000 | V19: =U19+T19+S19+R19+Q19 -> 0 | X19: 0 | Y19: =V19-X19 -> 0 | Z19: 04 | AA19: 2 | AB19: 1 | AC19: 1 | AE19: 2 | AG19: =AF19+AE19+AD19+AC19+AB19+AA19 -> 6 | AJ19: =AG19-AI19 -> 6 | AK19: 04 | AL19: 101 | AM19: 122 | AN19: 45 | AO19: 63 | AP19: 122 | AQ19: =AP19+AO19+AN19+AM19+AL19 -> 453 | AS19: 0 | AT19: =AQ19-AS19 -> 453
B20: 26/005 | C20: 111500 | D20: 120700 | E20: 39100 | F20: 70850 | G20: 105050 | H20: =SUM(C20:G20) -> 447200 | I20: 05 | J20: 258078.95 | K20: 189100 | M20: =SUM(J20:L20) -> 447178.95 | N20: =H20-M20 -> 21.05 | Q20: 1 | U20: 1 | V20: =U20+T20+S20+R20+Q20 -> 2 | X20: 0 | Y20: =V20-X20 -> 2 | Z20: 05 | AA20: 3 | AB20: 1 | AC20: 2 | AE20: 2 | AG20: =AF20+AE20+AD20+AC20+AB20+AA20 -> 8 | AJ20: =AG20-AI20 -> 8 | AK20: 05 | AL20: 56 | AM20: 77 | AN20: 32 | AO20: 48 | AP20: 59 | AQ20: =AP20+AO20+AN20+AM20+AL20 -> 272 | AS20: 0 | AT20: =AQ20-AS20 -> 272
B21: 26/006 | C21: 185600 | D21: 159850 | E21: 69150 | F21: 98350 | G21: 229500 | H21: =SUM(C21:G21) -> 742450 | I21: 06 | J21: 682500 | K21: 60000 | L21: -50 | M21: =SUM(J21:L21) -> 742450 | N21: =H21-M21 -> 0 | Q21: 4 | R21: 2 | S21: 1 | T21: 2 | V21: =U21+T21+S21+R21+Q21 -> 9 | X21: 0 | Y21: =V21-X21 -> 9 | Z21: 06 | AA21: 12 | AB21: 4 | AC21: 3 | AE21: 1 | AG21: =AF21+AE21+AD21+AC21+AB21+AA21 -> 20 | AJ21: =AG21-AI21 -> 20 | AK21: 06 | AL21: 119 | AM21: 121 | AN21: 67 | AO21: 75 | AP21: 141 | AQ21: =AP21+AO21+AN21+AM21+AL21 -> 523 | AS21: 0 | AT21: =AQ21-AS21 -> 523
B22: 26/007 | C22: 236950 | D22: 183950 | E22: 100500 | F22: 130600 | G22: 242950 | H22: =SUM(C22:G22) -> 894950 | I22: 07 | J22: 373100 | K22: 521900 | L22: -50 | M22: =SUM(J22:L22) -> 894950 | N22: =H22-M22 -> 0 | V22: =U22+T22+S22+R22+Q22 -> 0 | X22: 0 | Y22: =V22-X22 -> 0 | Z22: 07 | AA22: 7 | AB22: 4 | AC22: 1 | AG22: =AF22+AE22+AD22+AC22+AB22+AA22 -> 12 | AJ22: =AG22-AI22 -> 12 | AK22: 07 | AL22: 125 | AM22: 141 | AN22: 68 | AO22: 87 | AP22: 154 | AQ22: =AP22+AO22+AN22+AM22+AL22 -> 575 | AS22: 0 | AT22: =AQ22-AS22 -> 575
B23: 26/008 | C23: 43000 | D23: 40800 | E23: 2900 | F23: 28200 | G23: 102800 | H23: =SUM(C23:G23) -> 217700 | I23: 08 | K23: 217700 | M23: =SUM(J23:L23) -> 217700 | N23: =H23-M23 -> 0 | Q23: 1 | R23: 1 | U23: 1 | V23: =U23+T23+S23+R23+Q23 -> 3 | X23: 0 | Y23: =V23-X23 -> 3 | Z23: 08 | AG23: =AF23+AE23+AD23+AC23+AB23+AA23 -> 0 | AJ23: =AG23-AI23 -> 0 | AK23: 08 | AL23: 36 | AM23: 29 | AN23: 4 | AO23: 24 | AP23: 39 | AQ23: =AP23+AO23+AN23+AM23+AL23 -> 132 | AS23: 0 | AT23: =AQ23-AS23 -> 132
B24: 26/009 | C24: 99700 | D24: 127900 | E24: 19800 | F24: 32700 | G24: 87200 | H24: =SUM(C24:G24) -> 367300 | I24: 09 | J24: 86100 | K24: 281200 | M24: =SUM(J24:L24) -> 367300 | N24: =H24-M24 -> 0 | Q24: 2 | R24: 2 | V24: =U24+T24+S24+R24+Q24 -> 4 | X24: 0 | Y24: =V24-X24 -> 4 | Z24: 09 | AA24: 4 | AC24: 4 | AG24: =AF24+AE24+AD24+AC24+AB24+AA24 -> 8 | AJ24: =AG24-AI24 -> 8 | AK24: 09 | AL24: 54 | AM24: 87 | AN24: 20 | AO24: 34 | AP24: 58 | AQ24: =AP24+AO24+AN24+AM24+AL24 -> 253 | AS24: 0 | AT24: =AQ24-AS24 -> 253
B25: 26/010 | H25: =SUM(C25:G25) -> 0 | I25: 10 | M25: =SUM(J25:L25) -> 0 | N25: =H25-M25 -> 0 | V25: =U25+T25+S25+R25+Q25 -> 0 | X25: 0 | Y25: =V25-X25 -> 0 | Z25: 10 | AG25: =AF25+AE25+AD25+AC25+AB25+AA25 -> 0 | AJ25: =AG25-AI25 -> 0 | AK25: 10 | AQ25: =AP25+AO25+AN25+AM25+AL25 -> 0 | AS25: 0 | AT25: =AQ25-AS25 -> 0
B26: 26/011 | C26: 83800 | D26: 107100 | E26: 46050 | F26: 50900 | G26: 74300 | H26: =SUM(C26:G26) -> 362150 | I26: 11 | J26: 25200 | K26: 337000 | L26: -50 | M26: =SUM(J26:L26) -> 362150 | N26: =H26-M26 -> 0 | R26: 1 | S26: 1 | T26: 1 | V26: =U26+T26+S26+R26+Q26 -> 3 | X26: 0 | Y26: =V26-X26 -> 3 | Z26: 11 | AB26: 2 | AC26: 1 | AG26: =AF26+AE26+AD26+AC26+AB26+AA26 -> 3 | AJ26: =AG26-AI26 -> 3 | AK26: 11 | AL26: 66 | AM26: 105 | AN26: 39 | AO26: 48 | AP26: 69 | AQ26: =AP26+AO26+AN26+AM26+AL26 -> 327 | AS26: 0 | AT26: =AQ26-AS26 -> 327
B27: 26/012 | C27: 137600 | D27: 116250 | E27: 84800 | F27: 85200 | G27: 148150 | H27: =SUM(C27:G27) -> 572000 | I27: 12 | J27: 291375 | K27: 280650 | L27: -25 | M27: =SUM(J27:L27) -> 572000 | N27: =H27-M27 -> 0 | R27: 1 | S27: 1 | T27: 1 | V27: =U27+T27+S27+R27+Q27 -> 3 | X27: 0 | Y27: =V27-X27 -> 3 | Z27: 12 | AA27: 5 | AB27: 3 | AC27: 1 | AD27: 1 | AG27: =AF27+AE27+AD27+AC27+AB27+AA27 -> 10 | AJ27: =AG27-AI27 -> 10 | AK27: 12 | AL27: 91 | AM27: 71 | AN27: 62 | AO27: 72 | AP27: 109 | AQ27: =AP27+AO27+AN27+AM27+AL27 -> 405 | AS27: 0 | AT27: =AQ27-AS27 -> 405
B28: 26/013 | C28: 169600 | D28: 200000 | E28: 139800 | F28: 117100 | G28: 199150 | H28: =SUM(C28:G28) -> 825650 | I28: 13 | J28: 262150 | K28: 563500 | M28: =SUM(J28:L28) -> 825650 | N28: =H28-M28 -> 0 | S28: 1 | T28: 1 | V28: =U28+T28+S28+R28+Q28 -> 2 | X28: 0 | Y28: =V28-X28 -> 2 | Z28: 13 | AA28: 5 | AB28: 2 | AC28: 1 | AG28: =AF28+AE28+AD28+AC28+AB28+AA28 -> 8 | AJ28: =AG28-AI28 -> 8 | AK28: 13 | AL28: 104 | AM28: 98 | AN28: 70 | AO28: 61 | AP28: 101 | AQ28: =AP28+AO28+AN28+AM28+AL28 -> 434 | AS28: 0 | AT28: =AQ28-AS28 -> 434
B29: 26/014 | C29: 129500 | D29: 92700 | E29: 21400 | F29: 39500 | G29: 56000 | H29: =SUM(C29:G29) -> 339100 | I29: 14 | J29: 490000 | L29: -150900 | M29: =SUM(J29:L29) -> 339100 | N29: =H29-M29 -> 0 | Q29: 1 | T29: 2 | V29: =U29+T29+S29+R29+Q29 -> 3 | X29: 0 | Y29: =V29-X29 -> 3 | Z29: 14 | AA29: 5 | AB29: 1 | AC29: 1 | AG29: =AF29+AE29+AD29+AC29+AB29+AA29 -> 7 | AJ29: =AG29-AI29 -> 7 | AK29: 14 | AL29: 106 | AM29: 54 | AN29: 16 | AO29: 24 | AP29: 43 | AQ29: =AP29+AO29+AN29+AM29+AL29 -> 243 | AS29: 0 | AT29: =AQ29-AS29 -> 243
B30: 26/015 | H30: =SUM(C30:G30) -> 0 | I30: 15 | M30: =SUM(J30:L30) -> 0 | N30: =H30-M30 -> 0 | V30: =U30+T30+S30+R30+Q30 -> 0 | X30: 0 | Y30: =V30-X30 -> 0 | Z30: 15 | AG30: =AF30+AE30+AD30+AC30+AB30+AA30 -> 0 | AJ30: =AG30-AI30 -> 0 | AK30: 15 | AQ30: =AP30+AO30+AN30+AM30+AL30 -> 0 | AS30: 0 | AT30: =AQ30-AS30 -> 0
B31: 26/016 | C31: 171300 | D31: 147900 | E31: 58500 | F31: 112100 | G31: 115900 | H31: =SUM(C31:G31) -> 605700 | I31: 16 | J31: 1348200 | L31: -742500 | M31: =SUM(J31:L31) -> 605700 | N31: =H31-M31 -> 0 | U31: 1 | V31: =U31+T31+S31+R31+Q31 -> 1 | X31: 0 | Y31: =V31-X31 -> 1 | Z31: 16 | AA31: 8 | AB31: 2 | AC31: 1 | AG31: =AF31+AE31+AD31+AC31+AB31+AA31 -> 11 | AJ31: =AG31-AI31 -> 11 | AK31: 16 | AL31: 112 | AM31: 100 | AN31: 27 | AO31: 56 | AP31: 80 | AQ31: =AP31+AO31+AN31+AM31+AL31 -> 375 | AS31: 0 | AT31: =AQ31-AS31 -> 375
B32: 26/017 | C32: 29300 | D32: 23700 | E32: 15000 | F32: 17800 | G32: 37800 | H32: =SUM(C32:G32) -> 123600 | I32: 17 | K32: 60700 | L32: 62900 | M32: =SUM(J32:L32) -> 123600 | N32: =H32-M32 -> 0 | V32: =U32+T32+S32+R32+Q32 -> 0 | X32: 0 | Y32: =V32-X32 -> 0 | Z32: 17 | AG32: =AF32+AE32+AD32+AC32+AB32+AA32 -> 0 | AJ32: =AG32-AI32 -> 0 | AK32: 17 | AL32: 23 | AM32: 14 | AN32: 10 | AO32: 16 | AP32: 39 | AQ32: =AP32+AO32+AN32+AM32+AL32 -> 102 | AS32: 0 | AT32: =AQ32-AS32 -> 102
B33: 26/018 | H33: =SUM(C33:G33) -> 0 | I33: 18 | M33: =SUM(J33:L33) -> 0 | N33: =H33-M33 -> 0 | V33: =U33+T33+S33+R33+Q33 -> 0 | X33: 0 | Y33: =V33-X33 -> 0 | Z33: 18 | AG33: =AF33+AE33+AD33+AC33+AB33+AA33 -> 0 | AJ33: =AG33-AI33 -> 0 | AK33: 18 | AQ33: =AP33+AO33+AN33+AM33+AL33 -> 0 | AS33: 0 | AT33: =AQ33-AS33 -> 0
B34: 26/019 | H34: =SUM(C34:G34) -> 0 | I34: 19 | M34: =SUM(J34:L34) -> 0 | N34: =H34-M34 -> 0 | V34: =U34+T34+S34+R34+Q34 -> 0 | X34: 0 | Y34: =V34-X34 -> 0 | Z34: 19 | AG34: =AF34+AE34+AD34+AC34+AB34+AA34 -> 0 | AJ34: =AG34-AI34 -> 0 | AK34: 19 | AQ34: =AP34+AO34+AN34+AM34+AL34 -> 0 | AS34: 0 | AT34: =AQ34-AS34 -> 0
C36: =SUM(C12:C34) -> 2575150 | D36: =SUM(D12:D34) -> 2192450 | E36: =SUM(E12:E34) -> 957350 | F36: =SUM(F12:F34) -> 1252750 | G36: =SUM(G12:G34) -> 2182050 | H36: =SUM(H12:H34) -> 9159750 | J36: =SUM(J12:J34) -> 4920571.2 | K36: =SUM(K12:K35) -> 5184900 | L36: =SUM(L13:L34) -> -949742.25 | M36: =SUM(M12:M34) -> 9155728.9 | Q36: TOTAL ANULADAS | U36: =SUM(V12:V34) -> 53 | X36: =SUM(X12:X34) -> 0 | AA36: TOTAL PREMIADAS | AF36: =SUM(AG12:AG34) -> 135 | AI36: =SUM(AI12:AI34) -> 0 | AL36: TOTAL VENDIDAS | AP36: =SUM(AQ12:AQ34) -> 6044 | AS36: =SUM(AS12:AS34) -> 0
B38: DEBEN / SALIDA | J38: PAGAN / ENTRADA
B40: MARTIN GASTOS | D40: 0 | E40: DEPOSITOS | H40: =D41+C72 -> 10002770 | J40: DEUDA DE CAJA s/l/v | L40: 0 | M40: EXCEDENTE | N40: 0
B41: PREMIOS | D41: =J36 -> 4920571.2 | E41: PREST. PALP. | H41: 0 | J41: FALTANTE DE CAJA | L41: 0 | M41: MARTIN | N41: 0
B42: LIBRERIA | D42: 0 | E42: PREST. TELEKINO | H42: 0 | J42: PREST. PALP./ REVISTA | L42: 0 | M42: PREMIOS | N42: 0
B43: LIMPIEZA | D43: 0 | E43: PREST. JGOS. MENORES | H43: 0 | J43: PREST. TELEKINO | L43: 0 | N43: 0
B44: SODA/AGUA | D44: 0 | E44: IMPUESTOS | H44: 0 | J44: PREST. JGOS. MENORES | L44: 0 | N44: 0
B45: GASTOS VARIOS | D45: 0 | E45: OTROS | H45: =SUM(N12:N34) -> 4021.05 | L45: 0 | N45: 0
B47: SUB TOTAL | D47: =D40+D41+D42+D43+D44+D45+H41+H42+H43+H44+H45 -> 4924592.2 | G47: TOTAL | H47: =D47+H40 -> 14927362 | M47: SUB TOTAL | N47: =L40+L41+L42+L43+L44+L45+N40+N41+N42+N43+N44+N45 -> 0
C49: DETALLE RECAUDACION DE CAJA | H49: IMPORTE | J49: FECHA | L49: DETALLE CIERRE DE CAJA
...

Sheet 0201
A1: z
D2: PLANILLA DE RECAUDACION DIARIA DE APUESTA Y PREMIOS | M2: ='0101'!M2 -> 2025
D4: FECHA : | E4: 45170 | G4: RECAUDACION DEL DIA: | I4: 45169
C6: 26 | D6: SALDO DEL DIA ANTERIOR | G6: PREMIOS | H6: ='0101'!N76 -> 3234613.4
G7: EFECTIVO | H7: ='0101'!N77 -> 5828690
G8: TOTAL | H8: =H6+H7 -> 9063303.4 | Q8: TICKET ANULADOS | AA8: TICKET PREMIADOS | AL8: TICKET VENDIDOS
C10: MATUTINA | D10: VESPERT. | E10: SIESTA | F10: TARDE | G10: NOCT. | H10: TOTAL | J10: PREMIOS | K10: EFECTIVO | L10: MONEDAS | M10: TOTAL | N10: DIFER. | Q10: M | R10: V | S10: S | T10: T | U10: N | V10: TOTAL | X10: PRES. | Y10: DIFER. | AA10: ANT | AB10: M | AC10: V | AD10: S | AE10: T | AF10: N | AG10: TOTAL | AI10: PRES | AJ10: DIFER. | AL10: M | AM10: V | AN10: S | AO10: T | AP10: N | AQ10: TOTAL | AS10: PRES. | AT10: DIFER.
H11: =SUM(H12:H15) -> 626400
B12: 001 | C12: 91000 | D12: 32700 | E12: 3000 | F12: 27000 | G12: 83700 | H12: =SUM(C12:G12) -> 237400 | I12: 001 | J12: 21000 | K12: 215300 | M12: =SUM(J12:L12) -> 236300 | N12: =H12-M12 -> 1100 | R12: 1 | U12: 4 | V12: =U12+T12+S12+R12+Q12 -> 5 | X12: 0 | Y12: =V12-X12 -> 5 | Z12: V | AA12: 2 | AG12: =AF12+AE12+AD12+AC12+AB12+AA12 -> 2 | AI12: 0 | AJ12: =AG12-AI12 -> 2 | AL12: 58 | AM12: 25 | AN12: 2 | AO12: 24 | AP12: 51 | AQ12: =AP12+AO12+AN12+AM12+AL12 -> 160 | AS12: 0 | AT12: =AQ12-AS12 -> 160
B13: 002 | H13: =SUM(C13:G13) -> 0 | I13: 002 | M13: =SUM(J13:L13) -> 0 | N13: =H13-M13 -> 0 | V13: =U13+T13+S13+R13+Q13 -> 0 | X13: 0 | Y13: =V13-X13 -> 0 | Z13: L | AG13: =AF13+AE13+AD13+AC13+AB13+AA13 -> 0 | AJ13: =AG13-AI13 -> 0 | AQ13: =AP13+AO13+AN13+AM13+AL13 -> 0 | AS13: 0 | AT13: =AQ13-AS13 -> 0
B14: 003 | C14: 86950 | D14: 93800 | E14: 63200 | F14: 51450 | G14: 93600 | H14: =SUM(C14:G14) -> 389000 | I14: 003 | J14: 19600 | K14: 369400 | M14: =SUM(J14:L14) -> 389000 | N14: =H14-M14 -> 0 | U14: 1 | V14: =U14+T14+S14+R14+Q14 -> 1 | X14: 0 | Y14: =V14-X14 -> 1 | Z14: M | AA14: 2 | AG14: =AF14+AE14+AD14+AC14+AB14+AA14 -> 2 | AJ14: =AG14-AI14 -> 2 | AL14: 58 | AM14: 55 | AN14: 34 | AO14: 34 | AP14: 56 | AQ14: =AP14+AO14+AN14+AM14+AL14 -> 237 | AS14: 0 | AT14: =AQ14-AS14 -> 237
B15: 004 | H15: =SUM(C15:G15) -> 0 | I15: 004 | M15: =SUM(J15:L15) -> 0 | N15: =H15-M15 -> 0 | V15: =U15+T15+S15+R15+Q15 -> 0 | X15: 0 | Y15: =V15-X15 -> 0 | AG15: =AF15+AE15+AD15+AC15+AB15+AA15 -> 0 | AJ15: =AG15-AI15 -> 0 | AQ15: =AP15+AO15+AN15+AM15+AL15 -> 0 | AS15: 0 | AT15: =AQ15-AS15 -> 0
B16: 26/001 | C16: 129400 | D16: 33700 | E16: 25500 | F16: 45200 | G16: 85700 | H16: =SUM(C16:G16) -> 319500 | I16: 01 | J16: 1228500 | L16: -909000 | M16: =SUM(J16:L16) -> 319500 | N16: =H16-M16 -> 0 | R16: 1 | V16: =U16+T16+S16+R16+Q16 -> 1 | X16: 0 | Y16: =V16-X16 -> 1 | Z16: 01 | AA16: 1 | AB16: 3 | AG16: =AF16+AE16+AD16+AC16+AB16+AA16 -> 4 | AJ16: =AG16-AI16 -> 4 | AK16: 01 | AL16: 83 | AM16: 36 | AN16: 20 | AO16: 37 | AP16: 52 | AQ16: =AP16+AO16+AN16+AM16+AL16 -> 228 | AS16: 0 | AT16: =AQ16-AS16 -> 228
B17: 26/002 | C17: 246310 | D17: 207250 | E17: 120300 | F17: 161300 | G17: 233100 | H17: =SUM(C17:G17) -> 968260 | I17: 02 | J17: 108150 | K17: 860000 | M17: =SUM(J17:L17) -> 968150 | N17: =H17-M17 -> 110 | V17: =U17+T17+S17+R17+Q17 -> 0 | X17: 0 | Y17: =V17-X17 -> 0 | Z17: 02 | AA17: 7 | AB17: 4 | AC17: 2 | AE17: 1 | AG17: =AF17+AE17+AD17+AC17+AB17+AA17 -> 14 | AJ17: =AG17-AI17 -> 14 | AK17: 02 | AL17: 183 | AM17: 163 | AN17: 101 | AO17: 107 | AP17: 151 | AQ17: =AP17+AO17+AN17+AM17+AL17 -> 705 | AS17: 0 | AT17: =AQ17-AS17 -> 705
B18: 26/003 | C18: 131000 | D18: 147400 | E18: 74800 | F18: 118050 | G18: 158050 | H18: =SUM(C18:G18) -> 629300 | I18: 03 | J18: 227675 | K18: 401630 | L18: -5 | M18: =SUM(J18:L18) -> 629300 | N18: =H18-M18 -> 0 | V18: =U18+T18+S18+R18+Q18 -> 0 | X18: 0 | Y18: =V18-X18 -> 0 | Z18: 03 | AB18: 4 | AC18: 1 | AE18: 3 | AG18: =AF18+AE18+AD18+AC18+AB18+AA18 -> 8 | AJ18: =AG18-AI18 -> 8 | AK18: 03 | AL18: 66 | AM18: 69 | AN18: 40 | AO18: 58 | AP18: 91 | AQ18: =AP18+AO18+AN18+AM18+AL18 -> 324 | AS18: 0 | AT18: =AQ18-AS18 -> 324
B19: 26/004 | C19: 113600 | D19: 81650 | E19: 36850 | F19: 45900 | G19: 163600 | H19: =SUM(C19:G19) -> 441600 | I19: 04 | J19: 312900 | K19: 124700 | M19: =SUM(J19:L19) -> 437600 | N19: =H19-M19 -> 4000 | R19: 1 | U19: 1 | V19: =U19+T19+S19+R19+Q19 -> 2 | X19: 0 | Y19: =V19-X19 -> 2 | Z19: 04 | AA19: 2 | AB19: 1 | AC19: 1 | AD19: 2 | AG19: =AF19+AE19+AD19+AC19+AB19+AA19 -> 6 | AJ19: =AG19-AI19 -> 6 | AK19: 04 | AL19: 65 | AM19: 54 | AN19: 29 | AO19: 31 | AP19: 82 | AQ19: =AP19+AO19+AN19+AM19+AL19 -> 261 | AS19: 0 | AT19: =AQ19-AS19 -> 261
B20: 26/005 | C20: 62800 | D20: 96250 | E20: 35350 | F20: 100800 | G20: 76100 | H20: =SUM(C20:G20) -> 371300 | I20: 05 | J20: 84000 | K20: 287300 | M20: =SUM(J20:L20) -> 371300 | N20: =H20-M20 -> 0 | Q20: 1 | T20: 1 | V20: =U20+T20+S20+R20+Q20 -> 2 | X20: 0 | Y20: =V20-X20 -> 2 | Z20: 05 | AC20: 2 | AG20: =AF20+AE20+AD20+AC20+AB20+AA20 -> 2 | AJ20: =AG20-AI20 -> 2 | AK20: 05 | AL20: 47 | AM20: 55 | AN20: 29 | AO20: 41 | AP20: 43 | AQ20: =AP20+AO20+AN20+AM20+AL20 -> 215 | AS20: 0 | AT20: =AQ20-AS20 -> 215
B21: 26/006 | C21: 170350 | D21: 128200 | E21: 71400 | F21: 108800 | G21: 155550 | H21: =SUM(C21:G21) -> 634300 | I21: 06 | J21: 316750 | K21: 317600 | L21: -50 | M21: =SUM(J21:L21) -> 634300 | N21: =H21-M21 -> 0 | Q21: 1 | R21: 2 | T21: 4 | U21: 1 | V21: =U21+T21+S21+R21+Q21 -> 8 | X21: 0 | Y21: =V21-X21 -> 8 | Z21: 06 | AA21: 6 | AB21: 9 | AC21: 6 | AD21: 1 | AE21: 1 | AG21: =AF21+AE21+AD21+AC21+AB21+AA21 -> 23 | AJ21: =AG21-AI21 -> 23 | AK21: 06 | AL21: 109 | AM21: 96 | AN21: 51 | AO21: 75 | AP21: 108 | AQ21: =AP21+AO21+AN21+AM21+AL21 -> 439 | AS21: 0 | AT21: =AQ21-AS21 -> 439
B22: 26/007 | C22: 157600 | D22: 156300 | E22: 96500 | F22: 161500 | G22: 159550 | H22: =SUM(C22:G22) -> 731450 | I22: 07 | J22: 186900 | K22: 544500 | L22: 50 | M22: =SUM(J22:L22) -> 731450 | N22: =H22-M22 -> 0 | V22: =U22+T22+S22+R22+Q22 -> 0 | X22: 0 | Y22: =V22-X22 -> 0 | Z22: 07 | AA22: 3 | AB22: 1 | AC22: 1 | AD22: 1 | AG22: =AF22+AE22+AD22+AC22+AB22+AA22 -> 6 | AJ22: =AG22-AI22 -> 6 | AK22: 07 | AL22: 81 | AM22: 105 | AN22: 60 | AO22: 93 | AP22: 98 | AQ22: =AP22+AO22+AN22+AM22+AL22 -> 437 | AS22: 0 | AT22: =AQ22-AS22 -> 437
B23: 26/008 | C23: 53900 | D23: 55700 | E23: 4000 | F23: 47500 | G23: 59300 | H23: =SUM(C23:G23) -> 220400 | I23: 08 | J23: 185500 | K23: 34900 | M23: =SUM(J23:L23) -> 220400 | N23: =H23-M23 -> 0 | V23: =U23+T23+S23+R23+Q23 -> 0 | X23: 0 | Y23: =V23-X23 -> 0 | Z23: 08 | AA23: 1 | AB23: 4 | AE23: 2 | AG23: =AF23+AE23+AD23+AC23+AB23+AA23 -> 7 | AJ23: =AG23-AI23 -> 7 | AK23: 08 | AL23: 38 | AM23: 35 | AN23: 5 | AO23: 23 | AP23: 42 | AQ23: =AP23+AO23+AN23+AM23+AL23 -> 143 | AS23: 0 | AT23: =AQ23-AS23 -> 143
B24: 26/009 | C24: 98300 | D24: 73000 | E24: 25800 | F24: 39200 | G24: 136700 | H24: =SUM(C24:G24) -> 373000 | I24: 09 | J24: 51100 | K24: 323900 | L24: -2000 | M24: =SUM(J24:L24) -> 373000 | N24: =H24-M24 -> 0 | Q24: 1 | U24: 3 | V24: =U24+T24+S24+R24+Q24 -> 4 | X24: 0 | Y24: =V24-X24 -> 4 | Z24: 09 | AA24: 3 | AB24: 1 | AG24: =AF24+AE24+AD24+AC24+AB24+AA24 -> 4 | AJ24: =AG24-AI24 -> 4 | AK24: 09 | AL24: 48 | AM24: 51 | AN24: 18 | AO24: 30 | AP24: 71 | AQ24: =AP24+AO24+AN24+AM24+AL24 -> 218 | AS24: 0 | AT24: =AQ24-AS24 -> 218
B25: 26/010 | H25: =SUM(C25:G25) -> 0 | I25: 10 | M25: =SUM(J25:L25) -> 0 | N25: =H25-M25 -> 0 | V25: =U25+T25+S25+R25+Q25 -> 0 | X25: 0 | Y25: =V25-X25 -> 0 | Z25: 10 | AG25: =AF25+AE25+AD25+AC25+AB25+AA25 -> 0 | AJ25: =AG25-AI25 -> 0 | AK25: 10 | AQ25: =AP25+AO25+AN25+AM25+AL25 -> 0 | AS25: 0 | AT25: =AQ25-AS25 -> 0
B26: 26/011 | C26: 71700 | D26: 57100 | E26: 19900 | F26: 31900 | G26: 53600 | H26: =SUM(C26:G26) -> 234200 | I26: 11 | J26: 98700 | K26: 135500 | M26: =SUM(J26:L26) -> 234200 | N26: =H26-M26 -> 0 | Q26: 1 | V26: =U26+T26+S26+R26+Q26 -> 1 | X26: 0 | Y26: =V26-X26 -> 1 | Z26: 11 | AA26: 3 | AB26: 2 | AC26: 1 | AG26: =AF26+AE26+AD26+AC26+AB26+AA26 -> 6 | AJ26: =AG26-AI26 -> 6 | AK26: 11 | AL26: 56 | AM26: 53 | AN26: 20 | AO26: 39 | AP26: 45 | AQ26: =AP26+AO26+AN26+AM26+AL26 -> 213 | AS26: 0 | AT26: =AQ26-AS26 -> 213
B27: 26/012 | C27: 61250 | D27: 75800 | E27: 74850 | F27: 86000 | G27: 110650 | H27: =SUM(C27:G27) -> 408550 | I27: 12 | J27: 240500 | K27: 168050 | M27: =SUM(J27:L27) -> 408550 | N27: =H27-M27 -> 0 | Q27: 1 | R27: 2 | T27: 2 | V27: =U27+T27+S27+R27+Q27 -> 5 | X27: 0 | Y27: =V27-X27 -> 5 | Z27: 12 | AA27: 3 | AB27: 2 | AD27: 1 | AE27: 1 | AG27: =AF27+AE27+AD27+AC27+AB27+AA27 -> 7 | AJ27: =AG27-AI27 -> 7 | AK27: 12 | AL27: 49 | AM27: 61 | AN27: 56 | AO27: 67 | AP27: 102 | AQ27: =AP27+AO27+AN27+AM27+AL27 -> 335 | AS27: 0 | AT27: =AQ27-AS27 -> 335
B28: 26/013 | C28: 159000 | D28: 155700 | E28: 89800 | F28: 109500 | G28: 209600 | H28: =SUM(C28:G28) -> 723600 | I28: 13 | J28: 330750 | K28: 392900 | L28: -50 | M28: =SUM(J28:L28) -> 723600 | N28: =H28-M28 -> 0 | Q28: 2 | S28: 1 | T28: 2 | U28: 1 | V28: =U28+T28+S28+R28+Q28 -> 6 | X28: 0 | Y28: =V28-X28 -> 6 | Z28: 13 | AA28: 1 | AB28: 1 | AD28: 2 | AG28: =AF28+AE28+AD28+AC28+AB28+AA28 -> 4 | AJ28: =AG28-AI28 -> 4 | AK28: 13 | AL28: 103 | AM28: 85 | AN28: 46 | AO28: 39 | AP28: 100 | AQ28: =AP28+AO28+AN28+AM28+AL28 -> 373 | AS28: 0 | AT28: =AQ28-AS28 -> 373
B29: 26/014 | C29: 144400 | D29: 147650 | E29: 41300 | F29: 24300 | G29: 50300 | H29: =SUM(C29:G29) -> 407950 | I29: 14 | J29: 42000 | K29: 366050 | L29: 100 | M29: =SUM(J29:L29) -> 408150 | N29: =H29-M29 -> -200 | R29: 2 | V29: =U29+T29+S29+R29+Q29 -> 2 | X29: 0 | Y29: =V29-X29 -> 2 | Z29: 14 | AB29: 2 | AG29: =AF29+AE29+AD29+AC29+AB29+AA29 -> 2 | AJ29: =AG29-AI29 -> 2 | AK29: 14 | AL29: 87 | AM29: 87 | AN29: 32 | AO29: 18 | AP29: 36 | AQ29: =AP29+AO29+AN29+AM29+AL29 -> 260 | AS29: 0 | AT29: =AQ29-AS29 -> 260
B30: 26/015 | H30: =SUM(C30:G30) -> 0 | I30: 15 | M30: =SUM(J30:L30) -> 0 | N30: =H30-M30 -> 0 | V30: =U30+T30+S30+R30+Q30 -> 0 | X30: 0 | Y30: =V30-X30 -> 0 | Z30: 15 | AG30: =AF30+AE30+AD30+AC30+AB30+AA30 -> 0 | AJ30: =AG30-AI30 -> 0 | AK30: 15 | AQ30: =AP30+AO30+AN30+AM30+AL30 -> 0 | AS30: 0 | AT30: =AQ30-AS30 -> 0
B31: 26/016 | C31: 124900 | D31: 143300 | E31: 52100 | F31: 127900 | G31: 138500 | H31: =SUM(C31:G31) -> 586700 | I31: 16 | J31: 70700 | K31: 515000 | M31: =SUM(J31:L31) -> 585700 | N31: =H31-M31 -> 1000 | T31: 3 | V31: =U31+T31+S31+R31+Q31 -> 3 | X31: 0 | Y31: =V31-X31 -> 3 | Z31: 16 | AD31: 1 | AE31: 1 | AG31: =AF31+AE31+AD31+AC31+AB31+AA31 -> 2 | AJ31: =AG31-AI31 -> 2 | AK31: 16 | AL31: 60 | AM31: 76 | AN31: 27 | AO31: 64 | AP31: 80 | AQ31: =AP31+AO31+AN31+AM31+AL31 -> 307 | AS31: 0 | AT31: =AQ31-AS31 -> 307
B32: 26/017 | C32: 29500 | D32: 43200 | E32: 22600 | F32: 28700 | G32: 45600 | H32: =SUM(C32:G32) -> 169600 | I32: 17 | J32: 42000 | K32: 127600 | M32: =SUM(J32:L32) -> 169600 | N32: =H32-M32 -> 0 | Q32: 2 | V32: =U32+T32+S32+R32+Q32 -> 2 | X32: 0 | Y32: =V32-X32 -> 2 | Z32: 17 | AA32: 1 | AB32: 1 | AC32: 1 | AE32: 1 | AG32: =AF32+AE32+AD32+AC32+AB32+AA32 -> 4 | AJ32: =AG32-AI32 -> 4 | AK32: 17 | AL32: 25 | AM32: 32 | AN32: 18 | AO32: 21 | AP32: 38 | AQ32: =AP32+AO32+AN32+AM32+AL32 -> 134 | AS32: 0 | AT32: =AQ32-AS32 -> 134
B33: 26/018 | H33: =SUM(C33:G33) -> 0 | I33: 18 | M33: =SUM(J33:L33) -> 0 | N33: =H33-M33 -> 0 | V33: =U33+T33+S33+R33+Q33 -> 0 | X33: 0 | Y33: =V33-X33 -> 0 | Z33: 18 | AG33: =AF33+AE33+AD33+AC33+AB33+AA33 -> 0 | AJ33: =AG33-AI33 -> 0 | AK33: 18 | AQ33: =AP33+AO33+AN33+AM33+AL33 -> 0 | AS33: 0 | AT33: =AQ33-AS33 -> 0
B34: 26/019 | H34: =SUM(C34:G34) -> 0 | I34: 19 | M34: =SUM(J34:L34) -> 0 | N34: =H34-M34 -> 0 | V34: =U34+T34+S34+R34+Q34 -> 0 | X34: 0 | Y34: =V34-X34 -> 0 | Z34: 19 | AG34: =AF34+AE34+AD34+AC34+AB34+AA34 -> 0 | AJ34: =AG34-AI34 -> 0 | AK34: 19 | AQ34: =AP34+AO34+AN34+AM34+AL34 -> 0 | AS34: 0 | AT34: =AQ34-AS34 -> 0
C36: =SUM(C12:C34) -> 1931960 | D36: =SUM(D12:D34) -> 1728700 | E36: =SUM(E12:E34) -> 857250 | F36: =SUM(F12:F34) -> 1315000 | G36: =SUM(G12:G34) -> 2013200 | H36: =SUM(H12:H34) -> 7846110 | J36: =SUM(J12:J34) -> 3566725 | K36: =SUM(K12:K35) -> 5184330 | L36: =SUM(L13:L34) -> -910955 | M36: =SUM(M12:M34) -> 7840100 | Q36: TOTAL ANULADAS | U36: =SUM(V12:V34) -> 42 | X36: =SUM(X12:X34) -> 0 | AA36: TOTAL PREMIADAS | AF36: =SUM(AG12:AG34) -> 103 | AI36: =SUM(AI12:AI34) -> 0 | AL36: TOTAL VENDIDAS | AP36: =SUM(AQ12:AQ34) -> 4989 | AS36: =SUM(AS12:AS34) -> 0
B38: DEBEN / SALIDA | J38: PAGAN / ENTRADA
B40: MARTIN GASTOS | D40: 0 | E40: DEPOSITOS | H40: =D41+C72 -> 9159750 | J40: DEUDA DE CAJA s/l/v | L40: 0 | M40: EXCEDENTE | N40: 0
B41: PREMIOS | D41: =J36 -> 3566725 | E41: PREST. PALP. | H41: 0 | J41: FALTANTE DE CAJA | L41: 0 | M41: MARTIN | N41: 0
B42: LIBRERIA | D42: 0 | E42: PREST. TELEKINO | H42: 0 | J42: PREST. PALP./ REVISTA | L42: 0 | M42: PREMIOS | N42: 0
B43: LIMPIEZA | D43: 0 | E43: PREST. JGOS. MENORES | H43: 0 | J43: PREST. TELEKINO | L43: 0 | N43: 0
B44: SODA/AGUA | D44: 0 | E44: IMPUESTOS | H44: 0 | J44: PREST. JGOS. MENORES | L44: 0 | N44: 0
B45: GASTOS VARIOS | D45: 0 | E45: OTROS | H45: =SUM(N12:N34) -> 6010 | L45: 0 | N45: 0
B47: SUB TOTAL | D47: =D40+D41+D42+D43+D44+D45+H41+H42+H43+H44+H45 -> 3572735 | G47: TOTAL | H47: =D47+H40 -> 12732485 | M47: SUB TOTAL | N47: =L40+L41+L42+L43+L44+L45+N40+N41+N42+N43+N44+N45 -> 0
...

Sheet 0301
A1: z
D2: PLANILLA DE RECAUDACION DIARIA DE APUESTA Y PREMIOS | M2: ='0101'!M2 -> 2025
D4: FECHA : | E4: 45170 | G4: RECAUDACION DEL DIA: | I4: 45169
C6: 26 | D6: SALDO DEL DIA ANTERIOR | G6: PREMIOS | H6: ='0201'!N76 -> 3115613.4
G7: EFECTIVO | H7: ='0201'!N77 -> 4625790
G8: TOTAL | H8: =H6+H7 -> 7741403.4 | Q8: TICKET ANULADOS | AA8: TICKET PREMIADOS | AL8: TICKET VENDIDOS
C10: MATUTINA | D10: VESPERT. | E10: SIESTA | F10: TARDE | G10: NOCT. | H10: TOTAL | J10: PREMIOS | K10: EFECTIVO | L10: MONEDAS | M10: TOTAL | N10: DIFER. | Q10: M | R10: V | S10: S | T10: T | U10: N | V10: TOTAL | X10: PRES. | Y10: DIFER. | AA10: ANT | AB10: M | AC10: V | AD10: S | AE10: T | AF10: N | AG10: TOTAL | AI10: PRES | AJ10: DIFER. | AL10: M | AM10: V | AN10: S | AO10: T | AP10: N | AQ10: TOTAL | AS10: PRES. | AT10: DIFER.
H11: =SUM(H12:H15) -> 1010900
B12: 001 | C12: 160100 | D12: 50550 | E12: 8250 | F12: 28200 | G12: 82700 | H12: =SUM(C12:G12) -> 329800 | I12: 001 | J12: 27724.94 | K12: 300100 | M12: =SUM(J12:L12) -> 327824.94 | N12: =H12-M12 -> 1975.06 | V12: =U12+T12+S12+R12+Q12 -> 0 | X12: 0 | Y12: =V12-X12 -> 0 | Z12: V | AA12: 2 | AC12: 1 | AG12: =AF12+AE12+AD12+AC12+AB12+AA12 -> 3 | AI12: 0 | AJ12: =AG12-AI12 -> 3 | AL12: 85 | AM12: 26 | AN12: 10 | AO12: 11 | AP12: 37 | AQ12: =AP12+AO12+AN12+AM12+AL12 -> 169 | AS12: 0 | AT12: =AQ12-AS12 -> 169
B13: 002 | H13: =SUM(C13:G13) -> 0 | I13: 002 | M13: =SUM(J13:L13) -> 0 | N13: =H13-M13 -> 0 | V13: =U13+T13+S13+R13+Q13 -> 0 | X13: 0 | Y13: =V13-X13 -> 0 | Z13: L | AG13: =AF13+AE13+AD13+AC13+AB13+AA13 -> 0 | AJ13: =AG13-AI13 -> 0 | AQ13: =AP13+AO13+AN13+AM13+AL13 -> 0 | AS13: 0 | AT13: =AQ13-AS13 -> 0
B14: 003 | C14: 276650 | D14: 188350 | E14: 58900 | F14: 50900 | G14: 106300 | H14: =SUM(C14:G14) -> 681100 | I14: 003 | J14: 182260.91 | K14: 498839.09 | M14: =SUM(J14:L14) -> 681100 | N14: =H14-M14 -> 0 | T14: 2 | V14: =U14+T14+S14+R14+Q14 -> 2 | X14: 0 | Y14: =V14-X14 -> 2 | Z14: M | AA14: 1 | AC14: 3 | AG14: =AF14+AE14+AD14+AC14+AB14+AA14 -> 4 | AJ14: =AG14-AI14 -> 4 | AL14: 114 | AM14: 93 | AN14: 32 | AO14: 27 | AP14: 50 | AQ14: =AP14+AO14+AN14+AM14+AL14 -> 316 | AS14: 0 | AT14: =AQ14-AS14 -> 316
B15: 004 | H15: =SUM(C15:G15) -> 0 | I15: 004 | M15: =SUM(J15:L15) -> 0 | N15: =H15-M15 -> 0 | V15: =U15+T15+S15+R15+Q15 -> 0 | X15: 0 | Y15: =V15-X15 -> 0 | AG15: =AF15+AE15+AD15+AC15+AB15+AA15 -> 0 | AJ15: =AG15-AI15 -> 0 | AQ15: =AP15+AO15+AN15+AM15+AL15 -> 0 | AS15: 0 | AT15: =AQ15-AS15 -> 0
B16: 26/001 | C16: 125800 | D16: 92100 | E16: 25800 | F16: 44400 | G16: 106400 | H16: =SUM(C16:G16) -> 394500 | I16: 01 | J16: 100873.41 | K16: 293626.59 | M16: =SUM(J16:L16) -> 394500 | N16: =H16-M16 -> 0 | Q16: 3 | V16: =U16+T16+S16+R16+Q16 -> 3 | X16: 0 | Y16: =V16-X16 -> 3 | Z16: 01 | AB16: 4 | AG16: =AF16+AE16+AD16+AC16+AB16+AA16 -> 4 | AJ16: =AG16-AI16 -> 4 | AK16: 01 | AL16: 80 | AM16: 63 | AN16: 15 | AO16: 26 | AP16: 67 | AQ16: =AP16+AO16+AN16+AM16+AL16 -> 251 | AS16: 0 | AT16: =AQ16-AS16 -> 251
B17: 26/002 | C17: 305100 | D17: 239250 | E17: 162300 | F17: 152050 | G17: 330900 | H17: =SUM(C17:G17) -> 1189600 | I17: 02 | J17: 715607.96 | K17: 473992.04 | M17: =SUM(J17:L17) -> 1189600 | N17: =H17-M17 -> 0 | Q17: 1 | R17: 2 | V17: =U17+T17+S17+R17+Q17 -> 3 | X17: 0 | Y17: =V17-X17 -> 3 | Z17: 02 | AA17: 5 | AB17: 4 | AC17: 12 | AD17: 2 | AE17: 1 | AG17: =AF17+AE17+AD17+AC17+AB17+AA17 -> 24 | AJ17: =AG17-AI17 -> 24 | AK17: 02 | AL17: 193 | AM17: 145 | AN17: 147 | AO17: 118 | AP17: 204 | AQ17: =AP17+AO17+AN17+AM17+AL17 -> 807 | AS17: 0 | AT17: =AQ17-AS17 -> 807
B18: 26/003 | C18: 104100 | D18: 76000 | E18: 67400 | F18: 57900 | G18: 96550 | H18: =SUM(C18:G18) -> 401950 | I18: 03 | J18: 380621.83 | K18: 21328.17 | M18: =SUM(J18:L18) -> 401950 | N18: =H18-M18 -> 0 | V18: =U18+T18+S18+R18+Q18 -> 0 | X18: 0 | Y18: =V18-X18 -> 0 | Z18: 03 | AB18: 1 | AC18: 4 | AD18: 2 | AE18: 1 | AG18: =AF18+AE18+AD18+AC18+AB18+AA18 -> 8 | AJ18: =AG18-AI18 -> 8 | AK18: 03 | AL18: 58 | AM18: 49 | AN18: 43 | AO18: 42 | AP18: 59 | AQ18: =AP18+AO18+AN18+AM18+AL18 -> 251 | AS18: 0 | AT18: =AQ18-AS18 -> 251
B19: 26/004 | C19: 93900 | D19: 113200 | E19: 48980 | F19: 85550 | G19: 228750 | H19: =SUM(C19:G19) -> 570380 | I19: 04 | J19: 3154955.2 | L19: -2588575.2 | M19: =SUM(J19:L19) -> 566380 | N19: =H19-M19 -> 4000 | R19: 1 | V19: =U19+T19+S19+R19+Q19 -> 1 | X19: 0 | Y19: =V19-X19 -> 1 | Z19: 04 | AC19: 10 | AG19: =AF19+AE19+AD19+AC19+AB19+AA19 -> 10 | AJ19: =AG19-AI19 -> 10 | AK19: 04 | AL19: 67 | AM19: 65 | AN19: 34 | AO19: 45 | AP19: 113 | AQ19: =AP19+AO19+AN19+AM19+AL19 -> 324 | AS19: 0 | AT19: =AQ19-AS19 -> 324
B20: 26/005 | C20: 50900 | D20: 67600 | E20: 56100 | F20: 64900 | G20: 90800 | H20: =SUM(C20:G20) -> 330300 | I20: 05 | J20: 164699.22 | K20: 165600.78 | M20: =SUM(J20:L20) -> 330300 | N20: =H20-M20 -> 0 | Q20: 1 | V20: =U20+T20+S20+R20+Q20 -> 1 | X20: 0 | Y20: =V20-X20 -> 1 | Z20: 05 | AB20: 1 | AC20: 2 | AD20: 1 | AE20: 1 | AG20: =AF20+AE20+AD20+AC20+AB20+AA20 -> 5 | AJ20: =AG20-AI20 -> 5 | AK20: 05 | AL20: 28 | AM20: 50 | AN20: 40 | AO20: 45 | AP20: 58 | AQ20: =AP20+AO20+AN20+AM20+AL20 -> 221 | AS20: 0 | AT20: =AQ20-AS20 -> 221
B21: 26/006 | C21: 126500 | D21: 130800 | E21: 81500 | F21: 90300 | G21: 159900 | H21: =SUM(C21:G21) -> 589000 | I21: 06 | J21: 410086.8 | K21: 178913.2 | M21: =SUM(J21:L21) -> 589000 | N21: =H21-M21 -> 0 | Q21: 3 | R21: 2 | T21: 1 | V21: =U21+T21+S21+R21+Q21 -> 6 | X21: 0 | Y21: =V21-X21 -> 6 | Z21: 06 | AA21: 6 | AB21: 5 | AC21: 7 | AD21: 1 | AE21: 3 | AG21: =AF21+AE21+AD21+AC21+AB21+AA21 -> 22 | AJ21: =AG21-AI21 -> 22 | AK21: 06 | AL21: 84 | AM21: 92 | AN21: 58 | AO21: 64 | AP21: 101 | AQ21: =AP21+AO21+AN21+AM21+AL21 -> 399 | AS21: 0 | AT21: =AQ21-AS21 -> 399
B22: 26/007 | C22: 161250 | D22: 170650 | E22: 68150 | F22: 97350 | G22: 178300 | H22: =SUM(C22:G22) -> 675700 | I22: 07 | J22: 408586.71 | K22: 267113.29 | M22: =SUM(J22:L22) -> 675700 | N22: =H22-M22 -> 0 | V22: =U22+T22+S22+R22+Q22 -> 0 | X22: 0 | Y22: =V22-X22 -> 0 | Z22: 07 | AA22: 3 | AB22: 2 | AC22: 7 | AE22: 1 | AG22: =AF22+AE22+AD22+AC22+AB22+AA22 -> 13 | AJ22: =AG22-AI22 -> 13 | AK22: 07 | AL22: 117 | AM22: 107 | AN22: 46 | AO22: 66 | AP22: 120 | AQ22: =AP22+AO22+AN22+AM22+AL22 -> 456 | AS22: 0 | AT22: =AQ22-AS22 -> 456
B23: 26/008 | C23: 82200 | D23: 76300 | E23: 1500 | F23: 57800 | G23: 39200 | H23: =SUM(C23:G23) -> 257000 | I23: 08 | J23: 154000 | K23: 103000 | M23: =SUM(J23:L23) -> 257000 | N23: =H23-M23 -> 0 | Q23: 2 | V23: =U23+T23+S23+R23+Q23 -> 2 | X23: 0 | Y23: =V23-X23 -> 2 | Z23: 08 | AA23: 5 | AG23: =AF23+AE23+AD23+AC23+AB23+AA23 -> 5 | AJ23: =AG23-AI23 -> 5 | AK23: 08 | AL23: 36 | AM23: 50 | AN23: 1 | AO23: 39 | AP23: 30 | AQ23: =AP23+AO23+AN23+AM23+AL23 -> 156 | AS23: 0 | AT23: =AQ23-AS23 -> 156
B24: 26/009 | C24: 75800 | D24: 106500 | E24: 63500 | F24: 94000 | G24: 169200 | H24: =SUM(C24:G24) -> 509000 | I24: 09 | J24: 534276.8 | L24: -25276.8 | M24: =SUM(J24:L24) -> 509000 | N24: =H24-M24 -> 0 | R24: 1 | V24: =U24+T24+S24+R24+Q24 -> 1 | X24: 0 | Y24: =V24-X24 -> 1 | Z24: 09 | AB24: 1 | AC24: 9 | AE24: 1 | AG24: =AF24+AE24+AD24+AC24+AB24+AA24 -> 11 | AJ24: =AG24-AI24 -> 11 | AK24: 09 | AL24: 44 | AM24: 74 | AN24: 33 | AO24: 53 | AP24: 115 | AQ24: =AP24+AO24+AN24+AM24+AL24 -> 319 | AS24: 0 | AT24: =AQ24-AS24 -> 319
B25: 26/010 | H25: =SUM(C25:G25) -> 0 | I25: 10 | M25: =SUM(J25:L25) -> 0 | N25: =H25-M25 -> 0 | V25: =U25+T25+S25+R25+Q25 -> 0 | X25: 0 | Y25: =V25-X25 -> 0 | Z25: 10 | AG25: =AF25+AE25+AD25+AC25+AB25+AA25 -> 0 | AJ25: =AG25-AI25 -> 0 | AK25: 10 | AQ25: =AP25+AO25+AN25+AM25+AL25 -> 0 | AS25: 0 | AT25: =AQ25-AS25 -> 0
B26: 26/011 | C26: 52800 | D26: 68500 | E26: 41200 | F26: 34400 | G26: 74000 | H26: =SUM(C26:G26) -> 270900 | I26: 11 | J26: 65075.36 | K26: 205824.64 | M26: =SUM(J26:L26) -> 270900 | N26: =H26-M26 -> 0 | R26: 1 | V26: =U26+T26+S26+R26+Q26 -> 1 | X26: 0 | Y26: =V26-X26 -> 1 | Z26: 11 | AA26: 2 | AB26: 2 | AC26: 2 | AE26: 1 | AG26: =AF26+AE26+AD26+AC26+AB26+AA26 -> 7 | AJ26: =AG26-AI26 -> 7 | AK26: 11 | AL26: 53 | AM26: 53 | AN26: 38 | AO26: 39 | AP26: 64 | AQ26: =AP26+AO26+AN26+AM26+AL26 -> 247 | AS26: 0 | AT26: =AQ26-AS26 -> 247
B27: 26/012 | C27: 88300 | D27: 128750 | E27: 38250 | F27: 56500 | G27: 113400 | H27: =SUM(C27:G27) -> 425200 | I27: 12 | J27: 642301.61 | L27: -217101.61 | M27: =SUM(J27:L27) -> 425200 | N27: =H27-M27 -> 0 | R27: 2 | V27: =U27+T27+S27+R27+Q27 -> 2 | X27: 0 | Y27: =V27-X27 -> 2 | Z27: 12 | AA27: 2 | AB27: 1 | AC27: 12 | AG27: =AF27+AE27+AD27+AC27+AB27+AA27 -> 15 | AJ27: =AG27-AI27 -> 15 | AK27: 12 | AL27: 75 | AM27: 97 | AN27: 34 | AO27: 41 | AP27: 116 | AQ27: =AP27+AO27+AN27+AM27+AL27 -> 363 | AS27: 0 | AT27: =AQ27-AS27 -> 363
B28: 26/013 | C28: 121850 | D28: 154600 | E28: 99050 | F28: 93450 | G28: 168150 | H28: =SUM(C28:G28) -> 637100 | I28: 13 | J28: 160236.51 | K28: 476863.29 | M28: =SUM(J28:L28) -> 637099.8 | N28: =H28-M28 -> 0.2 | Q28: 2 | S28: 1 | V28: =U28+T28+S28+R28+Q28 -> 3 | X28: 0 | Y28: =V28-X28 -> 3 | Z28: 13 | AA28: 1 | AC28: 5 | AD28: 1 | AG28: =AF28+AE28+AD28+AC28+AB28+AA28 -> 7 | AJ28: =AG28-AI28 -> 7 | AK28: 13 | AL28: 63 | AM28: 81 | AN28: 54 | AO28: 43 | AP28: 81 | AQ28: =AP28+AO28+AN28+AM28+AL28 -> 322 | AS28: 0 | AT28: =AQ28-AS28 -> 322
B29: 26/014 | C29: 82400 | D29: 59200 | E29: 20800 | F29: 28200 | G29: 36400 | H29: =SUM(C29:G29) -> 227000 | I29: 14 | J29: 86824.23 | K29: 140175.77 | M29: =SUM(J29:L29) -> 227000 | N29: =H29-M29 -> 0 | Q29: 1 | V29: =U29+T29+S29+R29+Q29 -> 1 | X29: 0 | Y29: =V29-X29 -> 1 | Z29: 14 | AA29: 1 | AC29: 4 | AG29: =AF29+AE29+AD29+AC29+AB29+AA29 -> 5 | AJ29: =AG29-AI29 -> 5 | AK29: 14 | AL29: 65 | AM29: 37 | AN29: 15 | AO29: 18 | AP29: 30 | AQ29: =AP29+AO29+AN29+AM29+AL29 -> 165 | AS29: 0 | AT29: =AQ29-AS29 -> 165
B30: 26/015 | H30: =SUM(C30:G30) -> 0 | I30: 15 | M30: =SUM(J30:L30) -> 0 | N30: =H30-M30 -> 0 | V30: =U30+T30+S30+R30+Q30 -> 0 | X30: 0 | Y30: =V30-X30 -> 0 | Z30: 15 | AG30: =AF30+AE30+AD30+AC30+AB30+AA30 -> 0 | AJ30: =AG30-AI30 -> 0 | AK30: 15 | AQ30: =AP30+AO30+AN30+AM30+AL30 -> 0 | AS30: 0 | AT30: =AQ30-AS30 -> 0
B31: 26/016 | C31: 161900 | D31: 150700 | E31: 86500 | F31: 120900 | G31: 139300 | H31: =SUM(C31:G31) -> 659300 | I31: 16 | J31: 168403.71 | K31: 490896.29 | M31: =SUM(J31:L31) -> 659300 | N31: =H31-M31 -> 0 | V31: =U31+T31+S31+R31+Q31 -> 0 | X31: 0 | Y31: =V31-X31 -> 0 | Z31: 16 | AA31: 2 | AC31: 5 | AG31: =AF31+AE31+AD31+AC31+AB31+AA31 -> 7 | AJ31: =AG31-AI31 -> 7 | AK31: 16 | AL31: 79 | AM31: 77 | AN31: 43 | AO31: 55 | AP31: 85 | AQ31: =AP31+AO31+AN31+AM31+AL31 -> 339 | AS31: 0 | AT31: =AQ31-AS31 -> 339
B32: 26/017 | C32: 45850 | D32: 64950 | E32: 18750 | F32: 24200 | G32: 37800 | H32: =SUM(C32:G32) -> 191550 | I32: 17 | J32: 134498.71 | K32: 57051.29 | M32: =SUM(J32:L32) -> 191550 | N32: =H32-M32 -> 0 | V32: =U32+T32+S32+R32+Q32 -> 0 | X32: 0 | Y32: =V32-X32 -> 0 | Z32: 17 | AC32: 4 | AG32: =AF32+AE32+AD32+AC32+AB32+AA32 -> 4 | AJ32: =AG32-AI32 -> 4 | AK32: 17 | AL32: 44 | AM32: 44 | AN32: 24 | AO32: 17 | AP32: 22 | AQ32: =AP32+AO32+AN32+AM32+AL32 -> 151 | AS32: 0 | AT32: =AQ32-AS32 -> 151
B33: 26/018 | H33: =SUM(C33:G33) -> 0 | I33: 18 | M33: =SUM(J33:L33) -> 0 | N33: =H33-M33 -> 0 | V33: =U33+T33+S33+R33+Q33 -> 0 | X33: 0 | Y33: =V33-X33 -> 0 | Z33: 18 | AG33: =AF33+AE33+AD33+AC33+AB33+AA33 -> 0 | AJ33: =AG33-AI33 -> 0 | AK33: 18 | AQ33: =AP33+AO33+AN33+AM33+AL33 -> 0 | AS33: 0 | AT33: =AQ33-AS33 -> 0
B34: 26/019 | H34: =SUM(C34:G34) -> 0 | I34: 19 | M34: =SUM(J34:L34) -> 0 | N34: =H34-M34 -> 0 | V34: =U34+T34+S34+R34+Q34 -> 0 | X34: 0 | Y34: =V34-X34 -> 0 | Z34: 19 | AG34: =AF34+AE34+AD34+AC34+AB34+AA34 -> 0 | AJ34: =AG34-AI34 -> 0 | AK34: 19 | AQ34: =AP34+AO34+AN34+AM34+AL34 -> 0 | AS34: 0 | AT34: =AQ34-AS34 -> 0
C36: =SUM(C12:C34) -> 2115400 | D36: =SUM(D12:D34) -> 1938000 | E36: =SUM(E12:E34) -> 946930 | F36: =SUM(F12:F34) -> 1181000 | G36: =SUM(G12:G34) -> 2158050 | H36: =SUM(H12:H34) -> 8339380 | J36: =SUM(J12:J34) -> 7491034 | K36: =SUM(K12:K35) -> 3673324.4 | L36: =SUM(L13:L34) -> -2830953.6 | M36: =SUM(M12:M34) -> 8333404.7 | Q36: TOTAL ANULADAS | U36: =SUM(V12:V34) -> 26 | X36: =SUM(X12:X34) -> 0 | AA36: TOTAL PREMIADAS | AF36: =SUM(AG12:AG34) -> 154 | AI36: =SUM(AI12:AI34) -> 0 | AL36: TOTAL VENDIDAS | AP36: =SUM(AQ12:AQ34) -> 5256 | AS36: =SUM(AS12:AS34) -> 0
B38: DEBEN / SALIDA | J38: PAGAN / ENTRADA
B40: MARTIN GASTOS | D40: 0 | E40: DEPOSITOS | H40: =D41+C72 -> 7846009 | J40: DEUDA DE CAJA s/l/v | L40: 0 | M40: EXCEDENTE | N40: 0
B41: PREMIOS | D41: =J36 -> 7491034 | E41: PREST. PALP. | H41: 0 | J41: FALTANTE DE CAJA | L41: 0 | M41: MARTIN | N41: 0
B42: LIBRERIA | D42: 0 | E42: PREST. TELEKINO | H42: 0 | J42: PREST. PALP./ REVISTA | L42: 0 | M42: PREMIOS | N42: 0
B43: LIMPIEZA | D43: 0 | E43: PREST. JGOS. MENORES | H43: 0 | J43: PREST. TELEKINO | L43: 0 | N43: 0
B44: SODA/AGUA | D44: 0 | E44: IMPUESTOS | H44: 0 | J44: PREST. JGOS. MENORES | L44: 0 | N44: 0
B45: GASTOS VARIOS | D45: 0 | E45: OTROS | H45: =SUM(N12:N34) -> 5975.26 | L45: 0 | N45: 0
B47: SUB TOTAL | D47: =D40+D41+D42+D43+D44+D45+H41+H42+H43+H44+H45 -> 7497009.2 | G47: TOTAL | H47: =D47+H40 -> 15343018 | M47: SUB TOTAL | N47: =L40+L41+L42+L43+L44+L45+N40+N41+N42+N43+N44+N45 -> 0
...

Sheet 0401
A1: z
D2: PLANILLA DE RECAUDACION DIARIA DE APUESTA Y PREMIOS | M2: ='0101'!M2 -> 2025
D4: FECHA : | E4: 45170 | G4: RECAUDACION DEL DIA: | I4: 45169
C6: 26 | D6: SALDO DEL DIA ANTERIOR | G6: PREMIOS | H6: ='0301'!N76 -> 3115613.4
G7: EFECTIVO | H7: ='0301'!N77 -> 5160540
G8: TOTAL | H8: =H6+H7 -> 8276153.4 | Q8: TICKET ANULADOS | AA8: TICKET PREMIADOS | AL8: TICKET VENDIDOS
C10: MATUTINA | D10: VESPERT. | E10: SIESTA | F10: TARDE | G10: NOCT. | H10: TOTAL | J10: PREMIOS | K10: EFECTIVO | L10: MONEDAS | M10: TOTAL | N10: DIFER. | Q10: M | R10: V | S10: S | T10: T | U10: N | V10: TOTAL | X10: PRES. | Y10: DIFER. | AA10: ANT | AB10: M | AC10: V | AD10: S | AE10: T | AF10: N | AG10: TOTAL | AI10: PRES | AJ10: DIFER. | AL10: M | AM10: V | AN10: S | AO10: T | AP10: N | AQ10: TOTAL | AS10: PRES. | AT10: DIFER.
H11: =SUM(H12:H15) -> 727300
B12: 001 | C12: 135200 | D12: 31000 | E12: 2500 | F12: 47000 | G12: 83200 | H12: =SUM(C12:G12) -> 298900 | I12: 001 | J12: 14000 | K12: 284900 | M12: =SUM(J12:L12) -> 298900 | N12: =H12-M12 -> 0 | Q12: 1 | T12: 1 | V12: =U12+T12+S12+R12+Q12 -> 2 | X12: 0 | Y12: =V12-X12 -> 2 | Z12: V | AA12: 2 | AG12: =AF12+AE12+AD12+AC12+AB12+AA12 -> 2 | AI12: 0 | AJ12: =AG12-AI12 -> 2 | AL12: 92 | AM12: 24 | AN12: 4 | AO12: 16 | AP12: 37 | AQ12: =AP12+AO12+AN12+AM12+AL12 -> 173 | AS12: 0 | AT12: =AQ12-AS12 -> 173
B13: 002 | H13: =SUM(C13:G13) -> 0 | I13: 002 | M13: =SUM(J13:L13) -> 0 | N13: =H13-M13 -> 0 | V13: =U13+T13+S13+R13+Q13 -> 0 | X13: 0 | Y13: =V13-X13 -> 0 | Z13: L | AG13: =AF13+AE13+AD13+AC13+AB13+AA13 -> 0 | AJ13: =AG13-AI13 -> 0 | AQ13: =AP13+AO13+AN13+AM13+AL13 -> 0 | AS13: 0 | AT13: =AQ13-AS13 -> 0
B14: 003 | C14: 139700 | D14: 122500 | E14: 39400 | F14: 45500 | G14: 81300 | H14: =SUM(C14:G14) -> 428400 | I14: 003 | J14: 142598.97 | K14: 285900 | L14: -98.97 | M14: =SUM(J14:L14) -> 428400 | N14: =H14-M14 -> 0 | V14: =U14+T14+S14+R14+Q14 -> 0 | X14: 0 | Y14: =V14-X14 -> 0 | Z14: M | AA14: 4 | AB14: 1 | AC14: 1 | AG14: =AF14+AE14+AD14+AC14+AB14+AA14 -> 6 | AJ14: =AG14-AI14 -> 6 | AL14: 87 | AM14: 68 | AN14: 22 | AO14: 19 | AP14: 40 | AQ14: =AP14+AO14+AN14+AM14+AL14 -> 236 | AS14: 0 | AT14: =AQ14-AS14 -> 236
B15: 004 | H15: =SUM(C15:G15) -> 0 | I15: 004 | J15: 14000 | L15: -14000 | M15: =SUM(J15:L15) -> 0 | N15: =H15-M15 -> 0 | V15: =U15+T15+S15+R15+Q15 -> 0 | X15: 0 | Y15: =V15-X15 -> 0 | AG15: =AF15+AE15+AD15+AC15+AB15+AA15 -> 0 | AJ15: =AG15-AI15 -> 0 | AQ15: =AP15+AO15+AN15+AM15+AL15 -> 0 | AS15: 0 | AT15: =AQ15-AS15 -> 0
B16: 26/001 | C16: 197100 | D16: 94600 | E16: 19200 | F16: 53300 | G16: 91600 | H16: =SUM(C16:G16) -> 455800 | I16: 01 | J16: 101500 | K16: 196090 | L16: 158210 | M16: =SUM(J16:L16) -> 455800 | N16: =H16-M16 -> 0 | Q16: 4 | R16: 1 | S16: 1 | T16: 1 | U16: 2 | V16: =U16+T16+S16+R16+Q16 -> 9 | X16: 0 | Y16: =V16-X16 -> 9 | Z16: 01 | AC16: 4 | AD16: 1 | AG16: =AF16+AE16+AD16+AC16+AB16+AA16 -> 5 | AJ16: =AG16-AI16 -> 5 | AK16: 01 | AL16: 111 | AM16: 73 | AN16: 23 | AO16: 49 | AP16: 77 | AQ16: =AP16+AO16+AN16+AM16+AL16 -> 333 | AS16: 0 | AT16: =AQ16-AS16 -> 333
B17: 26/002 | C17: 263350 | D17: 217900 | E17: 173050 | F17: 160400 | G17: 283455 | H17: =SUM(C17:G17) -> 1098155 | I17: 02 | J17: 432420.1 | K17: 665750 | L17: -15.1 | M17: =SUM(J17:L17) -> 1098155 | N17: =H17-M17 -> 0 | Q17: 2 | V17: =U17+T17+S17+R17+Q17 -> 2 | X17: 0 | Y17: =V17-X17 -> 2 | Z17: 02 | AA17: 4 | AG17: =AF17+AE17+AD17+AC17+AB17+AA17 -> 4 | AJ17: =AG17-AI17 -> 4 | AK17: 02 | AL17: 184 | AM17: 130 | AN17: 128 | AO17: 100 | AP17: 170 | AQ17: =AP17+AO17+AN17+AM17+AL17 -> 712 | AS17: 0 | AT17: =AQ17-AS17 -> 712
B18: 26/003 | C18: 135800 | D18: 108700 | E18: 90200 | F18: 76800 | G18: 122500 | H18: =SUM(C18:G18) -> 534000 | I18: 03 | J18: 161700 | K18: 372300 | M18: =SUM(J18:L18) -> 534000 | N18: =H18-M18 -> 0 | V18: =U18+T18+S18+R18+Q18 -> 0 | X18: 0 | Y18: =V18-X18 -> 0 | Z18: 03 | AC18: 1 | AD18: 4 | AE18: 2 | AG18: =AF18+AE18+AD18+AC18+AB18+AA18 -> 7 | AJ18: =AG18-AI18 -> 7 | AK18: 03 | AL18: 81 | AM18: 67 | AN18: 42 | AO18: 40 | AP18: 77 | AQ18: =AP18+AO18+AN18+AM18+AL18 -> 307 | AS18: 0 | AT18: =AQ18-AS18 -> 307
B19: 26/004 | C19: 94300 | D19: 108300 | E19: 58000 | F19: 98000 | G19: 222000 | H19: =SUM(C19:G19) -> 580600 | I19: 04 | J19: 225400 | K19: 335100 | L19: 10087.4 | M19: =SUM(J19:L19) -> 570587.4 | N19: =H19-M19 -> 10012.6 | V19: =U19+T19+S19+R19+Q19 -> 0 | X19: 0 | Y19: =V19-X19 -> 0 | Z19: 04 | AA19: 2 | AB19: 2 | AC19: 1 | AG19: =AF19+AE19+AD19+AC19+AB19+AA19 -> 5 | AJ19: =AG19-AI19 -> 5 | AK19: 04 | AL19: 59 | AM19: 56 | AN19: 33 | AO19: 43 | AP19: 106 | AQ19: =AP19+AO19+AN19+AM19+AL19 -> 297 | AS19: 0 | AT19: =AQ19-AS19 -> 297
B20: 26/005 | C20: 114500 | D20: 64200 | E20: 13300 | F20: 30800 | G20: 72100 | H20: =SUM(C20:G20) -> 294900 | I20: 05 | J20: 10224.94 | K20: 284700 | L20: -24.94 | M20: =SUM(J20:L20) -> 294900 | N20: =H20-M20 -> 0 | Q20: 1 | V20: =U20+T20+S20+R20+Q20 -> 1 | X20: 0 | Y20: =V20-X20 -> 1 | Z20: 05 | AA20: 1 | AB20: 1 | AG20: =AF20+AE20+AD20+AC20+AB20+AA20 -> 2 | AJ20: =AG20-AI20 -> 2 | AK20: 05 | AL20: 42 | AM20: 45 | AN20: 8 | AO20: 20 | AP20: 34 | AQ20: =AP20+AO20+AN20+AM20+AL20 -> 149 | AS20: 0 | AT20: =AQ20-AS20 -> 149
B21: 26/006 | C21: 141900 | D21: 130100 | E21: 59900 | F21: 61500 | G21: 171800 | H21: =SUM(C21:G21) -> 565200 | I21: 06 | J21: 93274.56 | K21: 471925.74 | M21: =SUM(J21:L21) -> 565200.3 | N21: =H21-M21 -> -0.3 | Q21: 1 | R21: 2 | T21: 1 | V21: =U21+T21+S21+R21+Q21 -> 4 | X21: 0 | Y21: =V21-X21 -> 4 | Z21: 06 | AA21: 5 | AB21: 1 | AC21: 1 | AD21: 1 | AE21: 1 | AG21: =AF21+AE21+AD21+AC21+AB21+AA21 -> 9 | AJ21: =AG21-AI21 -> 9 | AK21: 06 | AL21: 88 | AM21: 79 | AN21: 47 | AO21: 45 | AP21: 85 | AQ21: =AP21+AO21+AN21+AM21+AL21 -> 344 | AS21: 0 | AT21: =AQ21-AS21 -> 344
B22: 26/007 | C22: 159650 | D22: 116300 | E22: 46000 | F22: 102050 | G22: 122500 | H22: =SUM(C22:G22) -> 546500 | I22: 07 | J22: 109900 | K22: 436600 | M22: =SUM(J22:L22) -> 546500 | N22: =H22-M22 -> 0 | V22: =U22+T22+S22+R22+Q22 -> 0 | X22: 0 | Y22: =V22-X22 -> 0 | Z22: 07 | AA22: 2 | AC22: 1 | AE22: 2 | AG22: =AF22+AE22+AD22+AC22+AB22+AA22 -> 5 | AJ22: =AG22-AI22 -> 5 | AK22: 07 | AL22: 97 | AM22: 98 | AN22: 37 | AO22: 77 | AP22: 92 | AQ22: =AP22+AO22+AN22+AM22+AL22 -> 401 | AS22: 0 | AT22: =AQ22-AS22 -> 401
B23: 26/008 | C23: 66300 | D23: 45605 | E23: 9000 | F23: 31100 | G23: 46095 | H23: =SUM(C23:G23) -> 198100 | I23: 08 | J23: 31850 | K23: 166250 | M23: =SUM(J23:L23) -> 198100 | N23: =H23-M23 -> 0 | Q23: 1 | V23: =U23+T23+S23+R23+Q23 -> 1 | X23: 0 | Y23: =V23-X23 -> 1 | Z23: 08 | AA23: 3 | AB23: 1 | AE23: 1 | AG23: =AF23+AE23+AD23+AC23+AB23+AA23 -> 5 | AJ23: =AG23-AI23 -> 5 | AK23: 08 | AL23: 34 | AM23: 34 | AN23: 16 | AO23: 25 | AP23: 30 | AQ23: =AP23+AO23+AN23+AM23+AL23 -> 139 | AS23: 0 | AT23: =AQ23-AS23 -> 139
B24: 26/009 | C24: 137900 | D24: 102050 | E24: 39550 | F24: 53900 | G24: 152800 | H24: =SUM(C24:G24) -> 486200 | I24: 09 | J24: 104300 | K24: 381000 | L24: 900 | M24: =SUM(J24:L24) -> 486200 | N24: =H24-M24 -> 0 | R24: 1 | V24: =U24+T24+S24+R24+Q24 -> 1 | X24: 0 | Y24: =V24-X24 -> 1 | Z24: 09 | AA24: 2 | AB24: 3 | AD24: 1 | AG24: =AF24+AE24+AD24+AC24+AB24+AA24 -> 6 | AJ24: =AG24-AI24 -> 6 | AK24: 09 | AL24: 76 | AM24: 64 | AN24: 29 | AO24: 35 | AP24: 91 | AQ24: =AP24+AO24+AN24+AM24+AL24 -> 295 | AS24: 0 | AT24: =AQ24-AS24 -> 295
B25: 26/010 | H25: =SUM(C25:G25) -> 0 | I25: 10 | M25: =SUM(J25:L25) -> 0 | N25: =H25-M25 -> 0 | V25: =U25+T25+S25+R25+Q25 -> 0 | X25: 0 | Y25: =V25-X25 -> 0 | Z25: 10 | AG25: =AF25+AE25+AD25+AC25+AB25+AA25 -> 0 | AJ25: =AG25-AI25 -> 0 | AK25: 10 | AQ25: =AP25+AO25+AN25+AM25+AL25 -> 0 | AS25: 0 | AT25: =AQ25-AS25 -> 0
B26: 26/011 | C26: 57700 | D26: 62000 | E26: 25200 | F26: 48000 | G26: 56900 | H26: =SUM(C26:G26) -> 249800 | I26: 11 | J26: 80087.4 | K26: 169712.6 | M26: =SUM(J26:L26) -> 249800 | N26: =H26-M26 -> 0 | V26: =U26+T26+S26+R26+Q26 -> 0 | X26: 0 | Y26: =V26-X26 -> 0 | Z26: 11 | AA26: 1 | AC26: 1 | AG26: =AF26+AE26+AD26+AC26+AB26+AA26 -> 2 | AJ26: =AG26-AI26 -> 2 | AK26: 11 | AL26: 51 | AM26: 59 | AN26: 31 | AO26: 50 | AP26: 55 | AQ26: =AP26+AO26+AN26+AM26+AL26 -> 246 | AS26: 0 | AT26: =AQ26-AS26 -> 246
B27: 26/012 | C27: 97200 | D27: 122050 | E27: 63050 | F27: 57700 | G27: 125600 | H27: =SUM(C27:G27) -> 465600 | I27: 12 | J27: 171454.95 | K27: 294145.04 | M27: =SUM(J27:L27) -> 465599.99 | N27: =H27-M27 -> 0.01 | Q27: 1 | U27: 1 | V27: =U27+T27+S27+R27+Q27 -> 2 | X27: 0 | Y27: =V27-X27 -> 2 | Z27: 12 | AA27: 2 | AB27: 3 | AC27: 4 | AD27: 1 | AE27: 3 | AG27: =AF27+AE27+AD27+AC27+AB27+AA27 -> 13 | AJ27: =AG27-AI27 -> 13 | AK27: 12 | AL27: 58 | AM27: 64 | AN27: 46 | AO27: 47 | AP27: 103 | AQ27: =AP27+AO27+AN27+AM27+AL27 -> 318 | AS27: 0 | AT27: =AQ27-AS27 -> 318
B28: 26/013 | C28: 140200 | D28: 182900 | E28: 70600 | F28: 74900 | G28: 140000 | H28: =SUM(C28:G28) -> 608600 | I28: 13 | J28: 225274.81 | K28: 383325.19 | M28: =SUM(J28:L28) -> 608600 | N28: =H28-M28 -> 0 | Q28: 1 | R28: 2 | S28: 1 | U28: 1 | V28: =U28+T28+S28+R28+Q28 -> 5 | X28: 0 | Y28: =V28-X28 -> 5 | Z28: 13 | AA28: 2 | AB28: 3 | AC28: 2 | AE28: 1 | AG28: =AF28+AE28+AD28+AC28+AB28+AA28 -> 8 | AJ28: =AG28-AI28 -> 8 | AK28: 13 | AL28: 72 | AM28: 83 | AN28: 36 | AO28: 33 | AP28: 66 | AQ28: =AP28+AO28+AN28+AM28+AL28 -> 290 | AS28: 0 | AT28: =AQ28-AS28 -> 290
B29: 26/014 | C29: 98400 | D29: 56500 | E29: 22000 | F29: 25500 | G29: 70400 | H29: =SUM(C29:G29) -> 272800 | I29: 14 | J29: 160049.61 | K29: 111800 | L29: 950 | M29: =SUM(J29:L29) -> 272799.61 | N29: =H29-M29 -> 0.39 | V29: =U29+T29+S29+R29+Q29 -> 0 | X29: 0 | Y29: =V29-X29 -> 0 | Z29: 14 | AA29: 4 | AB29: 1 | AD29: 1 | AE29: 2 | AG29: =AF29+AE29+AD29+AC29+AB29+AA29 -> 8 | AJ29: =AG29-AI29 -> 8 | AK29: 14 | AL29: 73 | AM29: 55 | AN29: 18 | AO29: 16 | AP29: 42 | AQ29: =AP29+AO29+AN29+AM29+AL29 -> 204 | AS29: 0 | AT29: =AQ29-AS29 -> 204
B30: 26/015 | H30: =SUM(C30:G30) -> 0 | I30: 15 | M30: =SUM(J30:L30) -> 0 | N30: =H30-M30 -> 0 | V30: =U30+T30+S30+R30+Q30 -> 0 | X30: 0 | Y30: =V30-X30 -> 0 | Z30: 15 | AG30: =AF30+AE30+AD30+AC30+AB30+AA30 -> 0 | AJ30: =AG30-AI30 -> 0 | AK30: 15 | AL30: 109 | AM30: 67 | AN30: 48 | AO30: 30 | AP30: 82 | AQ30: =AP30+AO30+AN30+AM30+AL30 -> 336 | AS30: 0 | AT30: =AQ30-AS30 -> 336
B31: 26/016 | C31: 167050 | D31: 134750 | E31: 93600 | F31: 64000 | G31: 145300 | H31: =SUM(C31:G31) -> 604700 | I31: 16 | J31: 182824.94 | K31: 421875.06 | M31: =SUM(J31:L31) -> 604700 | N31: =H31-M31 -> 0 | U31: 3 | V31: =U31+T31+S31+R31+Q31 -> 3 | X31: 0 | Y31: =V31-X31 -> 3 | Z31: 16 | AA31: 8 | AD31: 1 | AG31: =AF31+AE31+AD31+AC31+AB31+AA31 -> 9 | AJ31: =AG31-AI31 -> 9 | AK31: 16 | AL31: 28 | AM31: 17 | AN31: 8 | AO31: 16 | AP31: 35 | AQ31: =AP31+AO31+AN31+AM31+AL31 -> 104 | AS31: 0 | AT31: =AQ31-AS31 -> 104
B32: 26/017 | C32: 23550 | D32: 22900 | E32: 7400 | F32: 19400 | G32: 30200 | H32: =SUM(C32:G32) -> 103450 | I32: 17 | J32: 6999.99 | K32: 96450 | M32: =SUM(J32:L32) -> 103449.99 | N32: =H32-M32 -> 0.01 | V32: =U32+T32+S32+R32+Q32 -> 0 | X32: 0 | Y32: =V32-X32 -> 0 | Z32: 17 | AA32: 3 | AG32: =AF32+AE32+AD32+AC32+AB32+AA32 -> 3 | AJ32: =AG32-AI32 -> 3 | AK32: 17 | AQ32: =AP32+AO32+AN32+AM32+AL32 -> 0 | AS32: 0 | AT32: =AQ32-AS32 -> 0
B33: 26/018 | H33: =SUM(C33:G33) -> 0 | I33: 18 | M33: =SUM(J33:L33) -> 0 | N33: =H33-M33 -> 0 | V33: =U33+T33+S33+R33+Q33 -> 0 | X33: 0 | Y33: =V33-X33 -> 0 | Z33: 18 | AG33: =AF33+AE33+AD33+AC33+AB33+AA33 -> 0 | AJ33: =AG33-AI33 -> 0 | AK33: 18 | AQ33: =AP33+AO33+AN33+AM33+AL33 -> 0 | AS33: 0 | AT33: =AQ33-AS33 -> 0
B34: 26/019 | H34: =SUM(C34:G34) -> 0 | I34: 19 | M34: =SUM(J34:L34) -> 0 | N34: =H34-M34 -> 0 | V34: =U34+T34+S34+R34+Q34 -> 0 | X34: 0 | Y34: =V34-X34 -> 0 | Z34: 19 | AG34: =AF34+AE34+AD34+AC34+AB34+AA34 -> 0 | AJ34: =AG34-AI34 -> 0 | AK34: 19 | AQ34: =AP34+AO34+AN34+AM34+AL34 -> 0 | AS34: 0 | AT34: =AQ34-AS34 -> 0
C36: =SUM(C12:C34) -> 2169800 | D36: =SUM(D12:D34) -> 1722355 | E36: =SUM(E12:E34) -> 831950 | F36: =SUM(F12:F34) -> 1049850 | G36: =SUM(G12:G34) -> 2017750 | H36: =SUM(H12:H34) -> 7791705 | J36: =SUM(J12:J34) -> 2267860.3 | K36: =SUM(K12:K35) -> 5357823.6 | L36: =SUM(L13:L34) -> 156008.39 | M36: =SUM(M12:M34) -> 7781692.3 | Q36: TOTAL ANULADAS | U36: =SUM(V12:V34) -> 30 | X36: =SUM(X12:X34) -> 0 | AA36: TOTAL PREMIADAS | AF36: =SUM(AG12:AG34) -> 99 | AI36: =SUM(AI12:AI34) -> 0 | AL36: TOTAL VENDIDAS | AP36: =SUM(AQ12:AQ34) -> 4884 | AS36: =SUM(AS12:AS34) -> 0
B38: DEBEN / SALIDA | J38: PAGAN / ENTRADA
B40: MARTIN GASTOS | D40: 0 | E40: DEPOSITOS | H40: =D41+C72 -> 8339379.2 | J40: DEUDA DE CAJA s/l/v | L40: 0 | M40: EXCEDENTE | N40: 0
B41: PREMIOS | D41: =J36 -> 2267860.3 | E41: PREST. PALP. | H41: 0 | J41: FALTANTE DE CAJA | L41: 0 | M41: MARTIN | N41: 0
B42: LIBRERIA | D42: 0 | E42: PREST. TELEKINO | H42: 0 | J42: PREST. PALP./ REVISTA | L42: 0 | M42: PREMIOS | N42: 0
B43: LIMPIEZA | D43: 0 | E43: PREST. JGOS. MENORES | H43: 0 | J43: PREST. TELEKINO | L43: 0 | N43: 0
B44: SODA/AGUA | D44: 0 | E44: IMPUESTOS | H44: 0 | J44: PREST. JGOS. MENORES | L44: 0 | N44: 0
B45: GASTOS VARIOS | D45: 0 | E45: OTROS | H45: =SUM(N12:N34) -> 10012.71 | L45: 0 | N45: 0
B47: SUB TOTAL | D47: =D40+D41+D42+D43+D44+D45+H41+H42+H43+H44+H45 -> 2277873 | G47: TOTAL | H47: =D47+H40 -> 10617252 | M47: SUB TOTAL | N47: =L40+L41+L42+L43+L44+L45+N40+N41+N42+N43+N44+N45 -> 0
...

Sheet 0501
A1: z
D2: PLANILLA DE RECAUDACION DIARIA DE APUESTA Y PREMIOS | M2: ='0101'!M2 -> 2025
D4: FECHA : | E4: 45170 | G4: RECAUDACION DEL DIA: | I4: 45169
C6: 26 | D6: SALDO DEL DIA ANTERIOR | G6: PREMIOS | H6: ='0401'!N76 -> 4175700.8
G7: EFECTIVO | H7: ='0401'!N77 -> 3542790
G8: TOTAL | H8: =H6+H7 -> 7718490.8 | Q8: TICKET ANULADOS | AA8: TICKET PREMIADOS | AL8: TICKET VENDIDOS
C10: MATUTINA | D10: VESPERT. | E10: SIESTA | F10: TARDE | G10: NOCT. | H10: TOTAL | J10: PREMIOS | K10: EFECTIVO | L10: MONEDAS | M10: TOTAL | N10: DIFER. | Q10: M | R10: V | S10: S | T10: T | U10: N | V10: TOTAL | X10: PRES. | Y10: DIFER. | AA10: ANT | AB10: M | AC10: V | AD10: S | AE10: T | AF10: N | AG10: TOTAL | AI10: PRES | AJ10: DIFER. | AL10: M | AM10: V | AN10: S | AO10: T | AP10: N | AQ10: TOTAL | AS10: PRES. | AT10: DIFER.
H11: =SUM(H12:H15) -> 1031500
B12: 001 | C12: 187500 | D12: 35400 | E12: 4400 | F12: 22300 | G12: 148200 | H12: =SUM(C12:G12) -> 397800 | I12: 001 | J12: 147368.42 | K12: 250200 | M12: =SUM(J12:L12) -> 397568.42 | N12: =H12-M12 -> 231.58 | Q12: 2 | V12: =U12+T12+S12+R12+Q12 -> 2 | X12: 0 | Y12: =V12-X12 -> 2 | Z12: V | AA12: 3 | AC12: 1 | AG12: =AF12+AE12+AD12+AC12+AB12+AA12 -> 4 | AI12: 0 | AJ12: =AG12-AI12 -> 4 | AL12: 89 | AM12: 28 | AN12: 6 | AO12: 19 | AP12: 73 | AQ12: =AP12+AO12+AN12+AM12+AL12 -> 215 | AS12: 0 | AT12: =AQ12-AS12 -> 215
B13: 002 | E13: 52000 | F13: 65300 | G13: 101200 | H13: =SUM(C13:G13) -> 218500 | I13: 002 | J13: 92289.47 | K13: 126300 | L13: -89.47 | M13: =SUM(J13:L13) -> 218500 | N13: =H13-M13 -> 0 | S13: 1 | V13: =U13+T13+S13+R13+Q13 -> 1 | X13: 0 | Y13: =V13-X13 -> 1 | Z13: L | AA13: 1 | AB13: 1 | AE13: 4 | AG13: =AF13+AE13+AD13+AC13+AB13+AA13 -> 6 | AJ13: =AG13-AI13 -> 6 | AN13: 18 | AO13: 26 | AP13: 53 | AQ13: =AP13+AO13+AN13+AM13+AL13 -> 97 | AS13: 0 | AT13: =AQ13-AS13 -> 97
B14: 003 | C14: 227600 | D14: 137050 | E14: 19850 | F14: 14650 | G14: 16050 | H14: =SUM(C14:G14) -> 415200 | I14: 003 | J14: 126000 | K14: 289200 | M14: =SUM(J14:L14) -> 415200 | N14: =H14-M14 -> 0 | V14: =U14+T14+S14+R14+Q14 -> 0 | X14: 0 | Y14: =V14-X14 -> 0 | Z14: M | AA14: 4 | AB14: 1 | AG14: =AF14+AE14+AD14+AC14+AB14+AA14 -> 5 | AJ14: =AG14-AI14 -> 5 | AL14: 111 | AM14: 90 | AN14: 23 | AO14: 17 | AP14: 18 | AQ14: =AP14+AO14+AN14+AM14+AL14 -> 259 | AS14: 0 | AT14: =AQ14-AS14 -> 259
B15: 004 | H15: =SUM(C15:G15) -> 0 | I15: 004 | J15: 1060087.4 | L15: -1060087.4 | M15: =SUM(J15:L15) -> 0 | N15: =H15-M15 -> 0 | V15: =U15+T15+S15+R15+Q15 -> 0 | X15: 0 | Y15: =V15-X15 -> 0 | AG15: =AF15+AE15+AD15+AC15+AB15+AA15 -> 0 | AJ15: =AG15-AI15 -> 0 | AQ15: =AP15+AO15+AN15+AM15+AL15 -> 0 | AS15: 0 | AT15: =AQ15-AS15 -> 0
B16: 26/001 | C16: 190350 | D16: 85650 | E16: 20350 | F16: 39850 | G16: 108550 | H16: =SUM(C16:G16) -> 444750 | I16: 01 | J16: 252000 | K16: 192800 | L16: -50 | M16: =SUM(J16:L16) -> 444750 | N16: =H16-M16 -> 0 | Q16: 3 | S16: 1 | U16: 1 | V16: =U16+T16+S16+R16+Q16 -> 5 | X16: 0 | Y16: =V16-X16 -> 5 | Z16: 01 | AA16: 5 | AB16: 1 | AC16: 2 | AD16: 1 | AG16: =AF16+AE16+AD16+AC16+AB16+AA16 -> 9 | AJ16: =AG16-AI16 -> 9 | AK16: 01 | AL16: 108 | AM16: 65 | AN16: 27 | AO16: 28 | AP16: 65 | AQ16: =AP16+AO16+AN16+AM16+AL16 -> 293 | AS16: 0 | AT16: =AQ16-AS16 -> 293
B17: 26/002 | C17: 358350 | D17: 285900 | E17: 103750 | F17: 128650 | G17: 216050 | H17: =SUM(C17:G17) -> 1092700 | I17: 02 | J17: 651000 | K17: 441700 | M17: =SUM(J17:L17) -> 1092700 | N17: =H17-M17 -> 0 | Q17: 2 | R17: 2 | S17: 4 | T17: 1 | U17: 1 | V17: =U17+T17+S17+R17+Q17 -> 10 | X17: 0 | Y17: =V17-X17 -> 10 | Z17: 02 | AA17: 10 | AC17: 1 | AE17: 2 | AG17: =AF17+AE17+AD17+AC17+AB17+AA17 -> 13 | AJ17: =AG17-AI17 -> 13 | AK17: 02 | AL17: 215 | AM17: 155 | AN17: 96 | AO17: 98 | AP17: 187 | AQ17: =AP17+AO17+AN17+AM17+AL17 -> 751 | AS17: 0 | AT17: =AQ17-AS17 -> 751
B18: 26/003 | C18: 162000 | D18: 124200 | E18: 116000 | F18: 122300 | G18: 195300 | H18: =SUM(C18:G18) -> 719800 | I18: 03 | J18: 306600 | K18: 413200 | M18: =SUM(J18:L18) -> 719800 | N18: =H18-M18 -> 0 | V18: =U18+T18+S18+R18+Q18 -> 0 | X18: 0 | Y18: =V18-X18 -> 0 | Z18: 03 | AA18: 3 | AB18: 1 | AC18: 3 | AE18: 1 | AG18: =AF18+AE18+AD18+AC18+AB18+AA18 -> 8 | AJ18: =AG18-AI18 -> 8 | AK18: 03 | AL18: 79 | AM18: 75 | AN18: 61 | AO18: 48 | AP18: 100 | AQ18: =AP18+AO18+AN18+AM18+AL18 -> 363 | AS18: 0 | AT18: =AQ18-AS18 -> 363
B19: 26/004 | C19: 137850 | D19: 145050 | E19: 88000 | F19: 112350 | G19: 208100 | H19: =SUM(C19:G19) -> 691350 | I19: 04 | J19: 745500 | L19: -58150 | M19: =SUM(J19:L19) -> 687350 | N19: =H19-M19 -> 4000 | U19: 1 | V19: =U19+T19+S19+R19+Q19 -> 1 | X19: 0 | Y19: =V19-X19 -> 1 | Z19: 04 | AA19: 7 | AC19: 2 | AE19: 1 | AG19: =AF19+AE19+AD19+AC19+AB19+AA19 -> 10 | AJ19: =AG19-AI19 -> 10 | AK19: 04 | AL19: 62 | AM19: 83 | AN19: 45 | AO19: 58 | AP19: 104 | AQ19: =AP19+AO19+AN19+AM19+AL19 -> 352 | AS19: 0 | AT19: =AQ19-AS19 -> 352
B20: 26/005 | C20: 61100 | D20: 79900 | E20: 62200 | F20: 27200 | G20: 78400 | H20: =SUM(C20:G20) -> 308800 | I20: 05 | J20: 227500 | K20: 81300 | M20: =SUM(J20:L20) -> 308800 | N20: =H20-M20 -> 0 | Q20: 1 | R20: 4 | S20: 1 | V20: =U20+T20+S20+R20+Q20 -> 6 | X20: 0 | Y20: =V20-X20 -> 6 | Z20: 05 | AC20: 2 | AD20: 1 | AG20: =AF20+AE20+AD20+AC20+AB20+AA20 -> 3 | AJ20: =AG20-AI20 -> 3 | AK20: 05 | AL20: 36 | AM20: 45 | AN20: 25 | AO20: 17 | AP20: 41 | AQ20: =AP20+AO20+AN20+AM20+AL20 -> 164 | AS20: 0 | AT20: =AQ20-AS20 -> 164
B21: 26/006 | C21: 134300 | D21: 139800 | E21: 65600 | F21: 92100 | G21: 168300 | H21: =SUM(C21:G21) -> 600100 | I21: 06 | J21: 332150 | K21: 268000 | L21: -50 | M21: =SUM(J21:L21) -> 600100 | N21: =H21-M21 -> 0 | R21: 1 | T21: 1 | U21: 3 | V21: =U21+T21+S21+R21+Q21 -> 5 | X21: 0 | Y21: =V21-X21 -> 5 | Z21: 06 | AA21: 4 | AB21: 1 | AC21: 8 | AD21: 1 | AE21: 3 | AG21: =AF21+AE21+AD21+AC21+AB21+AA21 -> 17 | AJ21: =AG21-AI21 -> 17 | AK21: 06 | AL21: 64 | AM21: 96 | AN21: 45 | AO21: 49 | AP21: 97 | AQ21: =AP21+AO21+AN21+AM21+AL21 -> 351 | AS21: 0 | AT21: =AQ21-AS21 -> 351
B22: 26/007 | C22: 132550 | D22: 179850 | E22: 75600 | F22: 150300 | G22: 283050 | H22: =SUM(C22:G22) -> 821350 | I22: 07 | J22: 833773.2 | L22: -12423.2 | M22: =SUM(J22:L22) -> 821350 | N22: =H22-M22 -> 0 | V22: =U22+T22+S22+R22+Q22 -> 0 | X22: 0 | Y22: =V22-X22 -> 0 | Z22: 07 | AA22: 5 | AB22: 1 | AC22: 5 | AD22: 1 | AE22: 2 | AG22: =AF22+AE22+AD22+AC22+AB22+AA22 -> 14 | AJ22: =AG22-AI22 -> 14 | AK22: 07 | AL22: 99 | AM22: 130 | AN22: 57 | AO22: 105 | AP22: 157 | AQ22: =AP22+AO22+AN22+AM22+AL22 -> 548 | AS22: 0 | AT22: =AQ22-AS22 -> 548
